Workbook

Sheet Tur 1 2022
B2: Navn | C2: "Breidtind"
B3: Turnr | C3: 1
B4: Tur start | C4: 44594
B5: Tur slutt | C5: 44623
B7: Aktivitet | D7: Totalt | E7: 44594 | F7: =E7+1 -> 44595 | G7: =F7+1 -> 44596 | H7: =G7+1 -> 44597 | I7: =H7+1 -> 44598 | J7: =I7+1 -> 44599 | K7: =J7+1 -> 44600 | L7: =K7+1 -> 44601 | M7: =L7+1 -> 44602 | ... AI7: =AH7+1 -> 44624
B8: Fiske | C8: timer | D8: =SUM(E8:AI8) -> 463.5 | E8: 0 | F8: 0 | G8: 3.5 | H8: 24 | I8: 24 | J8: 20 | K8: 4 | L8: 24 | M8: 16 | N8: 0 | O8: 11 | P8: 24 | Q8: 24 | R8: 24 | S8: 24 | T8: 24 | U8: 24 | V8: 24 | W8: 24 | X8: 24 | Y8: 18 | Z8: 19 | AA8: 20 | AB8: 24 | AC8: 24 | AD8: 16 | AE8: 0 | AF8: 0 | AG8: 0 | AH8: 0 | AI8: 0
B9: Seiling | C9: timer | D9: =SUM(E9:AI9) -> 69 | E9: 0 | F9: 0 | G9: 3 | H9: 0 | I9: 0 | J9: 4 | K9: 0 | L9: 0 | M9: 8 | N9: 24 | O9: 13 | P9: 0 | Q9: 0 | R9: 0 | S9: 0 | T9: 0 | U9: 0 | V9: 0 | W9: 0 | X9: 0 | Y9: 0 | Z9: 5 | AA9: 4 | AB9: 0 | AC9: 0 | AD9: 8 | AE9: 0 | AF9: 0 | AG9: 0 | AH9: 0 | AI9: 0
B10: Teknisk (feil, problem) | C10: timer | D10: =SUM(E10:AI10) -> 6 | E10: 0 | F10: 0 | G10: 0 | H10: 0 | I10: 0 | J10: 0 | K10: 0 | L10: 0 | M10: 0 | N10: 0 | O10: 0 | P10: 0 | Q10: 0 | R10: 0 | S10: 0 | T10: 0 | U10: 0 | V10: 0 | W10: 0 | X10: 0 | Y10: 6 | Z10: 0 | AA10: 0 | AB10: 0 | AC10: 0 | AD10: 0 | AE10: 0 | AF10: 0 | AG10: 0 | AH10: 0 | AI10: 0
B11: Vasking | C11: timer | D11: =SUM(E11:AI11) -> 41 | E11: 0 | F11: 0 | G11: 0 | H11: 0 | I11: 0 | J11: 0 | K11: 0 | L11: 0 | M11: 0 | N11: 0 | O11: 0 | P11: 0 | Q11: 0 | R11: 0 | S11: 0 | T11: 0 | U11: 0 | V11: 0 | W11: 0 | X11: 0 | Y11: 0 | Z11: 0 | AA11: 0 | AB11: 0 | AC11: 0 | AD11: 0 | AE11: 24 | AF11: 17 | AG11: 0 | AH11: 0 | AI11: 0
B12: Lossing | C12: timer | D12: =SUM(E12:AI12) -> 0 | E12: 0 | F12: 0 | G12: 0 | H12: 0 | I12: 0 | J12: 0 | K12: 0 | L12: 0 | M12: 0 | N12: 0 | O12: 0 | P12: 0 | Q12: 0 | R12: 0 | S12: 0 | T12: 0 | U12: 0 | V12: 0 | W12: 0 | X12: 0 | Y12: 0 | Z12: 0 | AA12: 0 | AB12: 0 | AC12: 0 | AD12: 0 | AE12: 0 | AF12: 0 | AG12: 0 | AH12: 0 | AI12: 0
B13: Bunkring | C13: timer | D13: =SUM(E13:AI13) -> 7 | E13: 0 | F13: 0 | G13: 0 | H13: 0 | I13: 0 | J13: 0 | K13: 0 | L13: 0 | M13: 0 | N13: 0 | O13: 0 | P13: 0 | Q13: 0 | R13: 0 | S13: 0 | T13: 0 | U13: 0 | V13: 0 | W13: 0 | X13: 0 | Y13: 0 | Z13: 0 | AA13: 0 | AB13: 0 | AC13: 0 | AD13: 0 | AE13: 0 | AF13: 7 | AG13: 0 | AH13: 0 | AI13: 0
B14: Annet | C14: timer | D14: =SUM(E14:AI14) -> 37.5 | E14: 0 | F14: 0 | G14: 17.5 | H14: 0 | I14: 0 | J14: 0 | K14: 20 | L14: 0 | M14: 0 | N14: 0 | O14: 0 | P14: 0 | Q14: 0 | R14: 0 | S14: 0 | T14: 0 | U14: 0 | V14: 0 | W14: 0 | X14: 0 | Y14: 0 | Z14: 0 | AA14: 0 | AB14: 0 | AC14: 0 | AD14: 0 | AE14: 0 | AF14: 0 | AG14: 0 | AH14: 0 | AI14: 0
B15: SUM | C15: timer | D15: =SUM(E15:AI15) -> 624 | E15: =SUM(E8:E14) -> 0 | F15: =SUM(F8:F14) -> 0 | G15: =SUM(G8:G14) -> 24 | H15: =SUM(H8:H14) -> 24 | I15: =SUM(I8:I14) -> 24 | J15: =SUM(J8:J14) -> 24 | K15: =SUM(K8:K14) -> 24 | L15: =SUM(L8:L14) -> 24 | ... AI15: =SUM(AI8:AI14) -> 0
B17: Felt/område | C17: Navn | D17: =SUM(E17:AI17) -> 0 | I17: Mørekysten | J17: mørekysten | K17: breidsundet | L17: mørekysten | M17: mørekysten | N17: seilas på leia nordover | O17: fugeløybanken | P17: fugeløybanken | Q17: tromsøflaket | R17: Vestkant tromsøflaket | S17: Vestkant Tromsøflaket | T17: Vest kanten av tromsøflaket | U17: Vestkanten av tromsøflaket | V17: Vestkanten av tromsøflaket | W17: vest kanten av Tromsøflaket | X17: Vest av tromsø flaket | Y17: vest av tromsøflaket | Z17: vest av tromsøflaket | AA17: Fugeløybanken | AB17: Fugeløybanken | AC17: Fugeløybanken | AD17: fugeløybanken
B18: Tauetimer | C18: Timer | D18: =SUM(E18:AI18) -> 257 | I18: 8.5 | J18: 13 | K18: 0 | L18: 16.5 | M18: 9 | O18: 5.5 | P18: 22 | Q18: 18 | R18: 19 | S18: 21 | T18: 16.5 | U18: 21 | V18: 19 | W18: 13 | X18: 12 | Y18: 16 | Z18: 15,5 | AA18: 15 | AB18: 20,5 | AC18: 20,5 | AD18: 12
B19: Hal | C19: Antall | D19: =SUM(E19:AI19) -> 72 | E19: 1 | F19: 3 | I19: 3 | J19: 4 | K19: 0 | L19: 4 | M19: 2 | O19: 2 | P19: 4 | Q19: 4 | R19: 4 | S19: 4 | T19: 3 | U19: 4 | V19: 4 | W19: 3 | X19: 3 | Y19: 3 | Z19: 3 | AA19: 3 | AB19: 4 | AC19: 4 | AD19: 3
B20: Bruk (630/550) (eks 2xAlfredo) | C20: Type x antall | D20: =SUM(E20:AI20) -> 0 | E20: 1*630 | F20: 2*630 | I20: 2*630 | J20: 2*630 | K20: 0 | L20: 2*630 | M20: 2*630 | O20: 2*630 | P20: 2*630 | Q20: 2*630 | R20: 2*630 | S20: 2*630 | T20: 2*630 | U20: 2*630 | V20: 2*630 | W20: 2*630 | X20: 2*630 | Y20: 2*630 | Z20: 2*630 | AA20: 2*630 | AB20: 2*630 | AC20: 2*630 | AD20: 2*630
B21: Sjøtemperatur | C21: Grader
B23: Fangst pr tauetime kg | C23: =D25/D18 -> 3024.6732
A25: efangst | B25: Fangst total(produktvekt) | C25: (autosummering) | D25: =SUM(E25:AI25) -> 777341 | E25: =SUM(E26:E37) -> 4464 | F25: =SUM(F26:F37) -> 18400 | G25: =SUM(G26:G37) -> 0 | H25: =SUM(H26:H37) -> 0 | I25: =SUM(I26:I37) -> 44487 | J25: =SUM(J26:J37) -> 64954 | K25: =SUM(K26:K37) -> 0 | L25: =SUM(L26:L37) -> 63434 | ... AI25: =SUM(AI26:AI37) -> 0
B26: Torsk | C26: kg | D26: =SUM(E26:AI26) -> 191878 | I26: 92 | J26: 46 | K26: 0 | L26: 138 | M26: 368 | N26: 0 | O26: 10740 | P26: 25721 | Q26: 18175 | R26: 14762 | S26: 5796 | T26: 8351 | U26: 5912 | V26: 4520 | W26: 4479 | X26: 3184 | Y26: 2794 | Z26: 8129 | AA26: 12167 | AB26: 30364 | AC26: 29739 | AD26: 6401
B27: Hyse | C27: kg | D27: =SUM(E27:AI27) -> 288681 | F27: 47 | I27: 231 | J27: 324 | L27: 368 | M27: 1152 | O27: 1012 | P27: 4278 | Q27: 21022 | R27: 28015 | S27: 18124 | T27: 24104 | U27: 21533 | V27: 27465 | W27: 40919 | X27: 24525 | Y27: 25447 | Z27: 16889 | AA27: 5843 | AB27: 6625 | AC27: 7547 | AD27: 13211
B28: Sei N | C28: kg | D28: =SUM(E28:AI28) -> 263010 | E28: 4368 | F28: 17222 | I28: 43792 | J28: 64120 | L28: 61552 | M28: 27094 | O28: 2484 | P28: 9906 | Q28: 8050 | R28: 2581 | S28: 4208 | T28: 552 | U28: 554 | V28: 646 | W28: 139 | X28: 278 | Y28: 374 | Z28: 1154 | AA28: 2397 | AB28: 4482 | AC28: 5572 | AD28: 1485
B29: Sei S | C29: kg | D29: =SUM(E29:Y29) -> 0
B30: Uer rund | C30: kg | D30: =SUM(E30:AI30) -> 16798 | O30: 408 | P30: 578 | Q30: 1207 | R30: 1377 | S30: 3009 | T30: 1428 | U30: 1088 | V30: 1700 | W30: 1105 | X30: 1258 | Y30: 408 | Z30: 799 | AA30: 1018 | AB30: 378 | AC30: 578 | AD30: 459
B31: Uer j/c | C31: kg | D31: =SUM(E31:AI31) -> 5414 | X31: 3760 | Y31: 1280 | AB31: 374
B32: Uer hoder | C32: kg | D32: =SUM(E32:AI32) -> 0
B33: Blåkveite | C33: kg | D33: =SUM(E33:AI33) -> 5698 | S33: 396 | U33: 506 | V33: 418 | W33: 924 | X33: 902 | Y33: 2442 | AA33: 110
B34: Blåkveite hoder | C34: kg | D34: =SUM(E34:AI34) -> 0
B35: Reke | C35: kg | D35: =SUM(E35:AI35) -> 0
B36: Reke kok | C36: kg | D36: =SUM(E36:AI36) -> 0
B37: Bifangst/Annet | C37: kg | D37: =SUM(E37:AI37) -> 5862 | E37: 96 | F37: 1131 | I37: 372 | J37: 464 | L37: 1376 | M37: 871 | P37: 202 | Q37: 40 | S37: 170 | T37: 65 | W37: 45 | Z37: 45 | AA37: 175 | AB37: 455 | AC37: 310 | AD37: 45
A39: Maskin | B39: Bunkersforbruk | C39: ltr | D39: =SUM(E39:AI39) -> 326000 | E39: 7000 | F39: 8000 | G39: 3000 | H39: 6000 | I39: 11000 | J39: 8000 | K39: 9000 | L39: 12000 | M39: 13000 | N39: 16000 | O39: 13000 | P39: 13000 | Q39: 15000 | R39: 14000 | S39: 14000 | T39: 15000 | U39: 14000 | V39: 14000 | W39: 13000 | X39: 13000 | Y39: 11000 | Z39: 14000 | AA39: 14000 | AB39: 15000 | AC39: 15000 | AD39: 14000 | AE39: 5000 | AF39: 4000 | AG39: 3000 | AH39: 0 | AI39: 0
B40: Smørolje forbruk | C40: ltr | D40: =SUM(E40:AI40) -> 1200 | E40: 0 | F40: 0 | G40: 0 | H40: 0 | I40: 0 | J40: 0 | K40: 0 | L40: 0 | M40: 300 | N40: 0 | O40: 0 | P40: 200 | Q40: 0 | R40: 0 | S40: 0 | T40: 0 | U40: 200 | Y40: 0 | Z40: 300 | AA40: 0 | AB40: 0 | AC40: 0 | AD40: 200 | AE40: 0 | AF40: 0 | AG40: 0 | AH40: 0 | AI40: 0
N42: 15000 | O42: 15000 | P42: 16000 | Q42: 15000 | R42: 15000 | S42: 15000 | T42: 16000 | U42: 16000 | V42: 17000 | W42: 16000 | X42: 15000 | Y42: 15000 | Z42: 15000 | AA42: 13000
A44: Fabrikk | B44: Timer uten produksjon, totalt | C44: timer | D44: =SUM(E44:AI44) -> 66 | E44: 0 | F44: 0 | G44: 0 | H44: 0 | I44: 0 | J44: 0 | K44: 0 | L44: 0 | M44: 0 | N44: 0 | O44: 7 | P44: 5 | Q44: 0 | R44: 3 | S44: 6 | T44: 6 | U44: 9 | V44: 0 | W44: 0 | X44: 6 | Y44: 4 | Z44: 8 | AA44: 7 | AB44: 5 | AC44: 0 | AD44: 0 | AE44: 0 | AF44: 0 | AG44: 0 | AH44: 0 | AI44: 0
B45: Mangel på fisk | C45: timer | D45: =SUM(E45:AI45) -> 51 | E45: 0 | F45: 0 | G45: 0 | H45: 0 | I45: 0 | J45: 0 | K45: 0 | L45: 0 | M45: 0 | N45: 0 | O45: 7 | P45: 4 | Q45: 0 | R45: 0 | S45: 5 | T45: 6 | U45: 8 | V45: 0 | W45: 0 | X45: 0 | Y45: 4 | Z45: 5 | AA45: 7 | AB45: 5 | AC45: 0 | AD45: 0 | AE45: 0 | AF45: 0 | AG45: 0 | AH45: 0 | AI45: 0
B46: Tekniske problem | C46: timer | D46: =SUM(E46:AI46) -> 15 | E46: 0 | F46: 0 | G46: 0 | H46: 0 | I46: 0 | J46: 0 | K46: 0 | L46: 0 | M46: 0 | N46: 0 | O46: 0 | P46: 1 | Q46: 0 | R46: 3 | S46: 1 | T46: 0 | U46: 1 | V46: 0 | W46: 0 | X46: 6 | Y46: 0 | Z46: 3 | AA46: 0 | AB46: 0 | AC46: 0 | AD46: 0 | AE46: 0 | AF46: 0 | AG46: 0 | AH46: 0 | AI46: 0
B47: Andre årsaker | C47: timer | D47: =SUM(E47:AI47) -> 0 | E47: 0 | F47: 0 | G47: 0 | H47: 0 | I47: 0 | J47: 0 | K47: 0 | L47: 0 | M47: 0 | N47: 0 | O47: 0 | P47: 0 | Q47: 0 | R47: 0 | S47: 0 | T47: 0 | U47: 0 | V47: 0 | W47: 0 | X47: 0 | Y47: 0 | Z47: 0 | AA47: 0 | AB47: 0 | AC47: 0 | AD47: 0 | AE47: 0 | AF47: 0 | AG47: 0 | AH47: 0 | AI47: 0
B48: Ensilasje, råstoff | C48: kg | D48: =SUM(E48:Y48) -> 227000 | E48: 0 | F48: 0 | G48: 0 | H48: 0 | I48: 17000 | J48: 15000 | K48: 0 | L48: 15000 | M48: 7000 | N48: 0 | O48: 6000 | P48: 18000 | Q48: 20000 | R48: 20000 | S48: 17000 | T48: 15000 | U48: 15000 | V48: 15000 | W48: 20000 | X48: 17000 | Y48: 10000 | Z48: 21000 | AA48: 12000 | AB48: 19000 | AC48: 20000 | AD48: 10000 | AE48: 0 | AF48: 0 | AG48: 0 | AH48: 0 | AI48: 0
...

Sheet Tur 2 2022
B2: Navn | C2: "Breidtind"
B3: Turnr | C3: 1
B4: Tur start | C4: 44624
B5: Tur slutt | C5: 44657
B7: Aktivitet | D7: Totalt | E7: 44624 | F7: =E7+1 -> 44625 | G7: =F7+1 -> 44626 | H7: =G7+1 -> 44627 | I7: =H7+1 -> 44628 | J7: =I7+1 -> 44629 | K7: =J7+1 -> 44630 | L7: =K7+1 -> 44631 | M7: =L7+1 -> 44632 | ... AI7: =AH7+1 -> 44654
B8: Fiske | C8: timer | D8: =SUM(E8:AI8) -> 636 | E8: 17 | F8: 24 | G8: 24 | H8: 24 | I8: 24 | J8: 24 | K8: 19 | L8: 24 | M8: 24 | N8: 24 | O8: 24 | P8: 24 | Q8: 23 | R8: 24 | S8: 24 | T8: 24 | U8: 24 | V8: 0 | W8: 24 | X8: 15 | Y8: 4 | Z8: 24 | AA8: 24 | AB8: 24 | AC8: 24 | AD8: 24 | AE8: 15 | AF8: 19 | AG8: 20 | AH8: 24 | AI8: 0
B9: Seiling | C9: timer | D9: =SUM(E9:AI9) -> 38 | E9: 7 | F9: 0 | G9: 0 | H9: 0 | I9: 0 | J9: 0 | K9: 0 | L9: 0 | M9: 0 | N9: 0 | O9: 0 | P9: 0 | Q9: 0 | R9: 0 | S9: 0 | T9: 0 | U9: 0 | V9: 0 | W9: 0 | X9: 9 | Y9: 4 | Z9: 0 | AA9: 0 | AB9: 0 | AC9: 0 | AD9: 0 | AE9: 9 | AF9: 5 | AG9: 4 | AH9: 0 | AI9: 0
B10: Teknisk (feil, problem) | C10: timer | D10: =SUM(E10:AI10) -> 6 | E10: 0 | F10: 0 | G10: 0 | H10: 0 | I10: 0 | J10: 0 | K10: 5 | L10: 0 | M10: 0 | N10: 0 | O10: 0 | P10: 0 | Q10: 1 | R10: 0 | S10: 0 | T10: 0 | U10: 0 | V10: 0 | W10: 0 | X10: 0 | Y10: 0 | Z10: 0 | AA10: 0 | AB10: 0 | AC10: 0 | AD10: 0 | AE10: 0 | AF10: 0 | AG10: 0 | AH10: 0 | AI10: 0
B11: Vasking | C11: timer | D11: =SUM(E11:AI11) -> 6 | E11: 0 | F11: 0 | G11: 0 | H11: 0 | I11: 0 | J11: 0 | K11: 0 | L11: 0 | M11: 0 | N11: 0 | O11: 0 | P11: 0 | Q11: 0 | R11: 0 | S11: 0 | T11: 0 | U11: 0 | V11: 0 | W11: 0 | X11: 0 | Y11: 6 | Z11: 0 | AA11: 0 | AB11: 0 | AC11: 0 | AD11: 0 | AE11: 0 | AF11: 0 | AG11: 0 | AH11: 0 | AI11: 0
B12: Lossing | C12: timer | D12: =SUM(E12:AI12) -> 10 | E12: 0 | F12: 0 | G12: 0 | H12: 0 | I12: 0 | J12: 0 | K12: 0 | L12: 0 | M12: 0 | N12: 0 | O12: 0 | P12: 0 | Q12: 0 | R12: 0 | S12: 0 | T12: 0 | U12: 0 | V12: 0 | W12: 0 | X12: 0 | Y12: 10 | Z12: 0 | AA12: 0 | AB12: 0 | AC12: 0 | AD12: 0 | AE12: 0 | AF12: 0 | AG12: 0 | AH12: 0 | AI12: 0
B13: Bunkring | C13: timer | D13: =SUM(E13:AI13) -> 0 | E13: 0 | F13: 0 | G13: 0 | H13: 0 | I13: 0 | J13: 0 | K13: 0 | L13: 0 | M13: 0 | N13: 0 | O13: 0 | P13: 0 | Q13: 0 | R13: 0 | S13: 0 | T13: 0 | U13: 0 | V13: 0 | W13: 0 | X13: 0 | Y13: 0 | Z13: 0 | AA13: 0 | AB13: 0 | AC13: 0 | AD13: 0 | AE13: 0 | AF13: 0 | AG13: 0 | AH13: 0 | AI13: 0
B14: Annet | C14: timer | D14: =SUM(E14:AI14) -> 24 | E14: 0 | F14: 0 | G14: 0 | H14: 0 | I14: 0 | J14: 0 | K14: 0 | L14: 0 | M14: 0 | N14: 0 | O14: 0 | P14: 0 | Q14: 0 | R14: 0 | S14: 0 | T14: 0 | U14: 0 | V14: 24 | W14: 0 | X14: 0 | Y14: 0 | Z14: 0 | AA14: 0 | AB14: 0 | AC14: 0 | AD14: 0 | AE14: 0 | AF14: 0 | AG14: 0 | AH14: 0 | AI14: 0
B15: SUM | C15: timer | D15: =SUM(E15:AI15) -> 720 | E15: =SUM(E8:E14) -> 24 | F15: =SUM(F8:F14) -> 24 | G15: =SUM(G8:G14) -> 24 | H15: =SUM(H8:H14) -> 24 | I15: =SUM(I8:I14) -> 24 | J15: =SUM(J8:J14) -> 24 | K15: =SUM(K8:K14) -> 24 | L15: =SUM(L8:L14) -> 24 | ... AI15: =SUM(AI8:AI14) -> 0
B17: Felt/område | C17: Navn | D17: =SUM(E17:AI17) -> 0 | E17: Fugløybanken | F17: Kanten/Teisten | G17: Teisten | H17: Fugløybanken | I17: Fugløybanken | J17: Fugløybanken | K17: Fugløybanken | L17: Teisten/Kanten | M17: Teisten | N17: Fugløyb. | O17: Tromsøflaket | P17: Tromsøflaket | Q17: Tromsøflaket | R17: Tromsøflaket | S17: Tromsøflaket | T17: Tromsøflaket | U17: Tromsøflaket | V17: Tromsøflaket | W17: Fugløybanken | X17: Teisten/kanten | Y17: Malangsgrunnen | Z17: Fugløybanken | AA17: Teisten/Kanten | AB17: Tromsøflaket | AC17: Tromsøflaket | AD17: Tromsøflaket | AE17: Tromsøflaket | AF17: NØ-snaget/Liksnaget | AG17: Hjelmsøya | AH17: Nygrunnen
B18: Tauetimer | C18: Timer | D18: =SUM(E18:AI18) -> 423.2 | E18: 9 | F18: 18.5 | G18: 19 | H18: 10 | I18: 7 | J18: 4 | K18: 12 | L18: 21 | M18: 11 | N18: 16.5 | O18: 18.5 | P18: 9 | Q18: 20 | R18: 18 | S18: 17 | T18: 17.2 | U18: 19 | W18: 18 | X18: 12 | Y18: 4 | Z18: 14 | AA18: 19.5 | AB18: 17.5 | AC18: 15.5 | AD18: 14.5 | AE18: 9.5 | AF18: 13 | AG18: 16 | AH18: 23
B19: Hal | C19: Antall | D19: =SUM(E19:AI19) -> 83 | E19: 2 | F19: 3 | G19: 3 | H19: 2 | I19: 2 | J19: 1 | K19: 2 | L19: 4 | M19: 2 | N19: 3 | O19: 3 | P19: 2 | Q19: 4 | R19: 3 | S19: 3 | T19: 4 | U19: 4 | W19: 4 | X19: 2 | Y19: 1 | Z19: 3 | AA19: 4 | AB19: 4 | AC19: 3 | AD19: 3 | AE19: 2 | AF19: 3 | AG19: 3 | AH19: 4
B20: Bruk (630/550) (eks 2xAlfredo) | C20: Type x antall | D20: =SUM(E20:AI20) -> 0 | E20: 2*S630 | F20: 2*S630 | G20: 2*630 | H20: 2*630 | I20: 2*630 | J20: 2*630 | K20: 2*630 | L20: 2*630 | M20: 2*630 | N20: 2*630 | O20: 2*630 | P20: 2*630 | Q20: 2*630 | R20: 2*630 | S20: 2*630 | T20: 2*630 | U20: 2*630 | W20: 2*630 | X20: 2*630 | Y20: 2*630 | Z20: 2*630 | AA20: 2*630 | AB20: 2*630 | AC20: 2*630 | AD20: 2*630 | AE20: 2*630 | AF20: 2*630 | AG20: 2*630 | AH20: 2*630
B21: Sjøtemperatur | C21: Grader | F21: 6.6 | G21: 5.8 | H21: 6 | I21: 6 | K21: 7 | L21: 6 | M21: 6 | N21: 7 | O21: 6 | P21: 6 | Q21: 6 | R21: 6 | S21: 6 | T21: 6 | U21: 6
B23: Fangst pr tauetime kg | C23: =D25/D18 -> 2214.043
A25: efangst | B25: Fangst total(produktvekt) | C25: (autosummering) | D25: =SUM(E25:AI25) -> 936983 | E25: =SUM(E26:E37) -> 13897 | F25: =SUM(F26:F37) -> 35329 | G25: =SUM(G26:G37) -> 32378 | H25: =SUM(H26:H37) -> 41290 | I25: =SUM(I26:I37) -> 28066 | J25: =SUM(J26:J37) -> 29055 | K25: =SUM(K26:K37) -> 24277 | L25: =SUM(L26:L37) -> 45363 | ... AI25: =SUM(AI26:AI37) -> 0
B26: Torsk | C26: kg | D26: =SUM(E26:AI26) -> 141488 | E26: 10910 | F26: 6475 | G26: 4376 | H26: 10101 | I26: 9804 | J26: 7192 | K26: 3774 | L26: 4141 | M26: 2298 | N26: 1430 | O26: 1718 | P26: 1146 | Q26: 4072 | R26: 2438 | S26: 921 | T26: 2196 | U26: 3282 | V26: 0 | W26: 1886 | X26: 2625 | Y26: 1856 | Z26: 10851 | AA26: 4082 | AB26: 2994 | AC26: 4012 | AD26: 5237 | AE26: 5315 | AF26: 7462 | AG26: 16897 | AH26: 1997
B27: Hyse | C27: kg | D27: =SUM(E27:AI27) -> 606476 | E27: 2272 | F27: 26318 | G27: 25082 | H27: 28446 | I27: 13706 | J27: 14702 | K27: 13974 | L27: 34141 | M27: 13725 | N27: 29856 | O27: 23136 | P27: 31056 | Q27: 34176 | R27: 17280 | S27: 14112 | T27: 25776 | U27: 32358 | W27: 28230 | X27: 17319 | Y27: 3168 | Z27: 26414 | AA27: 28359 | AB27: 27536 | AC27: 22834 | AD27: 39986 | AE27: 30721 | AF27: 436 | AG27: 678 | AH27: 679
B28: Sei N | C28: kg | D28: =SUM(E28:AI28) -> 86890 | E28: 598 | F28: 480 | G28: 1472 | I28: 736 | J28: 94 | K28: 616 | L28: 239 | N28: 414 | Q28: 2576 | R28: 2484 | T28: 2806 | U28: 4050 | W28: 92 | X28: 276 | Y28: 368 | Z28: 640 | AA28: 274 | AB28: 1839 | AC28: 598 | AD28: 1396 | AE28: 1846 | AF28: 18060 | AG28: 3024 | AH28: 41912
B29: Sei S | C29: kg | D29: =SUM(E29:Y29) -> 0
B30: Uer rund | C30: kg | D30: =SUM(E30:AI30) -> 95987 | E30: 95 | F30: 1728 | G30: 1008 | H30: 2282 | I30: 3632 | J30: 7067 | K30: 5868 | L30: 6747 | M30: 1324 | N30: 3636 | O30: 4916 | P30: 2352 | Q30: 3781 | R30: 2859 | S30: 4072 | T30: 5030 | U30: 3732 | W30: 3532 | X30: 3268 | Y30: 1346 | Z30: 722 | AA30: 8678 | AB30: 6689 | AC30: 4290 | AD30: 3647 | AE30: 1053 | AF30: 234 | AG30: 1112 | AH30: 1287
B31: Uer j/c | C31: kg | D31: =SUM(E31:AI31) -> 0
B32: Uer hoder | C32: kg | D32: =SUM(E32:AI32) -> 0
B33: Blåkveite | C33: kg | D33: =SUM(E33:AI33) -> 4340 | F33: 228 | G33: 440 | H33: 216 | I33: 88 | N33: 396 | O33: 176 | Q33: 352 | R33: 260 | S33: 698 | T33: 400 | U33: 298 | X33: 44 | Y33: 484 | AE33: 260
B34: Blåkveite hoder | C34: kg | D34: =SUM(E34:AI34) -> 420 | H34: 200 | I34: 100 | Y34: 120
B35: Reke | C35: kg | D35: =SUM(E35:AI35) -> 0
B36: Reke kok | C36: kg | D36: =SUM(E36:AI36) -> 0
B37: Bifangst/Annet | C37: kg | D37: =SUM(E37:AI37) -> 1382 | E37: 22 | F37: 100 | H37: 45 | K37: 45 | L37: 95 | O37: 90 | Q37: 120 | R37: 80 | S37: 100 | T37: 100 | X37: 45 | Z37: 30 | AA37: 20 | AD37: 70 | AF37: 100 | AG37: 50 | AH37: 270
A39: Maskin | B39: Bunkersforbruk | C39: ltr | D39: =SUM(E39:AI39) -> 368000 | E39: 10000 | F39: 12000 | G39: 12000 | H39: 11000 | I39: 10000 | J39: 10000 | K39: 12000 | L39: 12000 | M39: 13000 | N39: 12000 | O39: 12000 | P39: 10000 | Q39: 13000 | R39: 13000 | S39: 13000 | T39: 13000 | U39: 13000 | V39: 8000 | W39: 13000 | X39: 11000 | Y39: 7000 | Z39: 12000 | AA39: 14000 | AB39: 12000 | AC39: 13000 | AD39: 13000 | AE39: 14000 | AF39: 14000 | AG39: 15000 | AH39: 14000 | AI39: 7000
B40: Smørolje forbruk | C40: ltr | D40: =SUM(E40:AI40) -> 1400 | E40: 0 | F40: 0 | G40: 0 | H40: 200 | I40: 0 | J40: 0 | K40: 0 | L40: 0 | M40: 200 | N40: 0 | O40: 0 | P40: 200 | Q40: 0 | R40: 0 | S40: 0 | T40: 0 | U40: 0 | V40: 0 | W40: 300 | X40: 0 | Y40: 0 | Z40: 0 | AA40: 0 | AB40: 0 | AC40: 200 | AD40: 0 | AE40: 0 | AF40: 0 | AG40: 0 | AH40: 0 | AI40: 300
A43: Fabrikk | B43: Timer uten produksjon, totalt | C43: timer | D43: =SUM(E43:AI43) -> 48 | E43: 0 | F43: 0 | G43: 0 | H43: 0 | I43: 6 | J43: 0 | K43: 1 | L43: 0 | M43: 0 | N43: 0 | O43: 0 | P43: 0 | Q43: 0 | R43: 6 | S43: 0 | T43: 0 | U43: 0 | V43: 3 | W43: 0 | X43: 10 | Y43: 22 | Z43: 0 | AA43: 0 | AB43: 0 | AC43: 0 | AD43: 0 | AE43: 0 | AF43: 0 | AG43: 0 | AH43: 0 | AI43: 0
B44: Mangel på fisk | C44: timer | D44: =SUM(E44:AI44) -> 39 | E44: 0 | F44: 0 | G44: 0 | H44: 0 | I44: 0 | J44: 0 | K44: 0 | L44: 0 | M44: 3 | N44: 0 | O44: 0 | P44: 0 | Q44: 2 | R44: 0 | S44: 0 | T44: 0 | U44: 0 | V44: 19 | W44: 0 | X44: 0 | Y44: 0 | Z44: 0 | AA44: 0 | AB44: 0 | AC44: 0 | AD44: 0 | AE44: 2 | AF44: 6 | AG44: 7 | AH44: 0 | AI44: 0
B45: Tekniske problem | C45: timer | D45: =SUM(E45:AI45) -> 50 | E45: 0 | F45: 4 | G45: 2 | H45: 4 | I45: 6 | J45: 2 | K45: 2 | L45: 2 | M45: 2 | N45: 2 | O45: 2 | P45: 2 | Q45: 2 | R45: 6 | S45: 0 | T45: 2 | U45: 0 | V45: 3 | W45: 2 | X45: 4 | Y45: 0 | Z45: 1 | AA45: 0 | AB45: 0 | AC45: 0 | AD45: 0 | AE45: 0 | AF45: 0 | AG45: 0 | AH45: 0 | AI45: 0
B46: Andre årsaker | C46: timer | D46: =SUM(E46:AI46) -> 0 | E46: 0 | F46: 0 | G46: 0 | H46: 0 | I46: 0 | J46: 0 | K46: 0 | L46: 0 | M46: 0 | N46: 0 | O46: 0 | P46: 0 | Q46: 0 | R46: 0 | S46: 0 | T46: 0 | U46: 0 | V46: 0 | W46: 0 | X46: 0 | Y46: 0 | Z46: 0 | AA46: 0 | AB46: 0 | AC46: 0 | AD46: 0 | AE46: 0 | AF46: 0 | AG46: 0 | AH46: 0 | AI46: 0
B47: Ensilasje, råstoff | C47: kg | D47: =SUM(E47:AI47) -> 367000 | E47: 0 | F47: 0 | G47: 0 | H47: 0 | I47: 0 | J47: 0 | K47: 0 | L47: 0 | M47: 0 | N47: 0 | O47: 0 | P47: 0 | Q47: 0 | R47: 0 | S47: 200000 | T47: 0 | U47: 0 | V47: 0 | W47: 65000 | X47: 0 | Y47: 0 | Z47: 0 | AA47: 0 | AB47: 0 | AC47: 0 | AD47: 102000 | AE47: 0 | AF47: 0 | AG47: 0 | AH47: 0 | AI47: 0
B48: Ensilasje, syreforbruk | C48: kg | D48: =SUM(O48:AI48) -> 15000 | E48: 0 | F48: 0 | G48: 0 | H48: 0 | I48: 0 | J48: 0 | K48: 0 | L48: 0 | M48: 0 | N48: 0 | O48: 0 | P48: 0 | Q48: 0 | R48: 0 | S48: 8000 | T48: 0 | U48: 0 | V48: 0 | W48: 2800 | X48: 0 | Y48: 0 | Z48: 0 | AA48: 0 | AB48: 0 | AC48: 0 | AD48: 4200 | AE48: 0 | AF48: 0 | AG48: 0 | AH48: 0 | AI48: 0
...

Sheet Ark2

Sheet Tur 3 2022 
B2: Navn | C2: "Breidtind"
B3: Turnr | C3: 3
B4: Tur start | C4: 44656
B5: Tur slutt | C5: 44690
B7: Aktivitet | D7: Totalt | E7: 44656 | F7: =E7+1 -> 44657 | G7: =F7+1 -> 44658 | H7: =G7+1 -> 44659 | I7: =H7+1 -> 44660 | J7: =I7+1 -> 44661 | K7: =J7+1 -> 44662 | L7: =K7+1 -> 44663 | M7: =L7+1 -> 44664 | ... AM7: =AL7+1 -> 44690
B8: Fiske | C8: timer | D8: =SUM(E8:AI8) -> 549.5 | E8: 0 | F8: 0 | G8: 0 | H8: 0 | I8: 0 | J8: 5.5 | K8: 24 | L8: 24 | M8: 24 | N8: 24 | O8: 24 | P8: 24 | Q8: 24 | R8: 24 | S8: 24 | T8: 24 | U8: 24 | V8: 24 | W8: 24 | X8: 24 | Y8: 24 | Z8: 13 | AA8: 16 | AB8: 24 | AC8: 24 | AD8: 24 | AE8: 24 | AF8: 24 | AG8: 24 | AH8: 11 | AI8: 0 | AJ8: 0 | AK8: 0 | AL8: 0 | AM8: 0
B9: Seiling | C9: timer | D9: =SUM(E9:AI9) -> 37.5 | E9: 0 | F9: 0 | G9: 0 | H9: 0 | I9: 19 | J9: 18.5 | K9: 0 | L9: 0 | M9: 0 | N9: 0 | O9: 0 | P9: 0 | Q9: 0 | R9: 0 | S9: 0 | T9: 0 | U9: 0 | V9: 0 | W9: 0 | X9: 0 | Y9: 0 | Z9: 0 | AA9: 0 | AB9: 0 | AC9: 0 | AD9: 0 | AE9: 0 | AF9: 0 | AG9: 0 | AH9: 0 | AI9: 0 | AJ9: 0 | AK9: 0 | AL9: 0 | AM9: 0
B10: Teknisk (feil, problem) | C10: timer | D10: =SUM(E10:AI10) -> 72 | E10: 0 | F10: 24 | G10: 24 | H10: 24 | I10: 0 | J10: 0 | K10: 0 | L10: 0 | M10: 0 | N10: 0 | O10: 0 | P10: 0 | Q10: 0 | R10: 0 | S10: 0 | T10: 0 | U10: 0 | V10: 0 | W10: 0 | X10: 0 | Y10: 0 | Z10: 0 | AA10: 0 | AB10: 0 | AC10: 0 | AD10: 0 | AE10: 0 | AF10: 0 | AG10: 0 | AH10: 0 | AI10: 0 | AJ10: 0 | AK10: 0 | AL10: 0 | AM10: 0
B11: Vasking | C11: timer | D11: =SUM(E11:AI11) -> 13 | E11: 0 | F11: 0 | G11: 0 | H11: 0 | I11: 0 | J11: 0 | K11: 0 | L11: 0 | M11: 0 | N11: 0 | O11: 0 | P11: 0 | Q11: 0 | R11: 0 | S11: 0 | T11: 0 | U11: 0 | V11: 0 | W11: 0 | X11: 0 | Y11: 0 | Z11: 0 | AA11: 0 | AB11: 0 | AC11: 0 | AD11: 0 | AE11: 0 | AF11: 0 | AG11: 0 | AH11: 13 | AI11: 0 | AJ11: 0 | AK11: 0 | AL11: 0 | AM11: 0
B12: Lossing | C12: timer | D12: =SUM(E12:AI12) -> 15 | E12: 15 | F12: 0 | G12: 0 | H12: 0 | I12: 0 | J12: 0 | K12: 0 | L12: 0 | M12: 0 | N12: 0 | O12: 0 | P12: 0 | Q12: 0 | R12: 0 | S12: 0 | T12: 0 | U12: 0 | V12: 0 | W12: 0 | X12: 0 | Y12: 0 | Z12: 0 | AA12: 0 | AB12: 0 | AC12: 0 | AD12: 0 | AE12: 0 | AF12: 0 | AG12: 0 | AH12: 0 | AI12: 0 | AJ12: 0 | AK12: 0 | AL12: 0 | AM12: 0
B13: Bunkring | C13: timer | D13: =SUM(E13:AI13) -> 5 | E13: 0 | F13: 0 | G13: 0 | H13: 0 | I13: 5 | J13: 0 | K13: 0 | L13: 0 | M13: 0 | N13: 0 | O13: 0 | P13: 0 | Q13: 0 | R13: 0 | S13: 0 | T13: 0 | U13: 0 | V13: 0 | W13: 0 | X13: 0 | Y13: 0 | Z13: 0 | AA13: 0 | AB13: 0 | AC13: 0 | AD13: 0 | AE13: 0 | AF13: 0 | AG13: 0 | AH13: 0 | AI13: 0 | AJ13: 0 | AK13: 0 | AL13: 0 | AM13: 0
B14: Annet | C14: timer | D14: =SUM(E14:AI14) -> 19 | E14: 0 | F14: 0 | G14: 0 | H14: 0 | I14: 0 | J14: 0 | K14: 0 | L14: 0 | M14: 0 | N14: 0 | O14: 0 | P14: 0 | Q14: 0 | R14: 0 | S14: 0 | T14: 0 | U14: 0 | V14: 0 | W14: 0 | X14: 0 | Y14: 0 | Z14: 11 | AA14: 8 | AB14: 0 | AC14: 0 | AD14: 0 | AE14: 0 | AF14: 0 | AG14: 0 | AH14: 0 | AI14: 0 | AJ14: 0 | AK14: 0 | AL14: 0 | AM14: 0
B15: SUM | C15: timer | D15: =SUM(E15:AI15) -> 711 | E15: =SUM(E8:E14) -> 15 | F15: =SUM(F8:F14) -> 24 | G15: =SUM(G8:G14) -> 24 | H15: =SUM(H8:H14) -> 24 | I15: =SUM(I8:I14) -> 24 | J15: =SUM(J8:J14) -> 24 | K15: =SUM(K8:K14) -> 24 | L15: =SUM(L8:L14) -> 24 | ... AM15: =SUM(AM8:AM14) -> 0
B17: Felt/område | C17: Navn | D17: =SUM(E17:AI17) -> 0 | J17: sentralbanken | K17: sentralbanken | L17: sentralbanken | M17: sentralbanken | N17: sentralbanken | O17: sentralbanken | P17: sentralbanken | Q17: sentralbanken | R17: sentralbanken | S17: sentralbanken | T17: sør i smutthullet | U17: sør i smutthullet | V17: sør i smutthullet | W17: sør i smutthullet | X17: smutthullet sør | Y17: sentralbanken | Z17: sentralbanken | AA17: sentralbanken | AB17: sentralbanken | AC17: smutthullet sør | AD17: smutthullet sør | AE17: smutthullet sør | AF17: sentralbanken
B18: Tauetimer | C18: Timer | D18: =SUM(E18:AI18) -> 432 | J18: 5.5 | K18: 17 | L18: 19 | M18: 22 | N18: 21.5 | O18: 17 | P18: 21.5 | Q18: 21.5 | R18: 20 | S18: 21 | T18: 19 | U18: 21,5 | V18: 20 | W18: 20 | X18: 20 | Y18: 18 | Z18: 12 | AA18: 10.5 | AB18: 18 | AC18: 23 | AD18: 22 | AE18: 16 | AF18: 20 | AG18: 19.5 | AH18: 8
B19: Hal | C19: Antall | D19: =SUM(E19:AI19) -> 84 | J19: 2 | K19: 3 | L19: 3 | M19: 4 | N19: 4 | O19: 3 | P19: 4 | Q19: 4 | R19: 4 | S19: 4 | T19: 3 | U19: 4 | V19: 4 | W19: 4 | X19: 4 | Y19: 3 | Z19: 2 | AA19: 2 | AB19: 3 | AC19: 4 | AD19: 4 | AE19: 2 | AF19: 4 | AG19: 4 | AH19: 2
B20: Bruk (630/550) (eks 2xAlfredo) | C20: Type x antall | D20: =SUM(E20:AI20) -> 0 | J20: cosmos 3000 | K20: cosmos 3000 | L20: cosmos 3000 | M20: cosmos 3000 | N20: cosmos 3000 | O20: cosmos3000 | P20: cosmos 3000 | Q20: cosmos 3000 | R20: cosmos 3000 | S20: cosmos 3000 | T20: cosmos 3000 | U20: cosmos 3000 | V20: cosmos 3000 | W20: cosmos 3000 | X20: cosmos 3000 | Y20: cosmos 3000 | Z20: cosmos 3000 | AA20: cismos 3000 | AB20: cosmos 3000 | AC20: cosmos 3000 | AD20: cosmos3000 | AE20: cosmos 3000 | AF20: cosmos 3000 | AG20: cosmos 3000 | AH20: cosmos 3000
B21: Sjøtemperatur | C21: Grader | L21: 0
B23: Fangst pr tauetime kg | C23: =D25/D18 -> 1126.6389
A25: efangst | B25: Fangst total(produktvekt) | C25: (autosummering) | D25: =SUM(E25:AI25) -> 486708 | E25: =SUM(E26:E37) -> 0 | F25: =SUM(F26:F37) -> 0 | G25: =SUM(G26:G37) -> 0 | H25: =SUM(H26:H37) -> 0 | I25: =SUM(I26:I37) -> 0 | J25: =SUM(J26:J37) -> 3747 | K25: =SUM(K26:K37) -> 17497 | L25: =SUM(L26:L37) -> 24916 | ... AM25: =SUM(AM26:AM37) -> 0
B26: Torsk | C26: kg | D26: =SUM(E26:AI26) -> 0
B27: Hyse | C27: kg | D27: =SUM(E27:AI27) -> 0
B28: Sei N | C28: kg | D28: =SUM(E28:AI28) -> 0
B29: Sei S | C29: kg | D29: =SUM(E29:Y29) -> 0
B30: Uer rund | C30: kg | D30: =SUM(E30:AI30) -> 0
B31: Uer j/c | C31: kg | D31: =SUM(E31:AI31) -> 0
B32: Uer hoder | C32: kg | D32: =SUM(E32:AI32) -> 0
B33: Blåkveite | C33: kg | D33: =SUM(E33:AL33) -> 0
B34: Blåkveite hoder | C34: kg | D34: =SUM(E34:AI34) -> 0
B35: Reke | C35: kg | D35: =SUM(E35:AI35) -> 396546 | J35: 1562 | K35: 13464 | L35: 23656 | M35: 23880 | N35: 14742 | O35: 14742 | P35: 18858 | Q35: 18648 | R35: 11697 | S35: 21966 | T35: 23877 | U35: 23583 | V35: 17031 | W35: 18858 | X35: 22197 | Y35: 24003 | Z35: 10983 | AA35: 9408 | AB35: 11529 | AC35: 12201 | AD35: 16905 | AE35: 11214 | AF35: 10563 | AG35: 13314 | AH35: 7665
B36: Reke kok | C36: kg | D36: =SUM(E36:AI36) -> 90162 | J36: 2185 | K36: =2788+1245 -> 4033 | L36: 1260 | M36: 4629 | N36: 8573 | O36: 4600 | P36: 4494 | Q36: 2644 | R36: 4912 | S36: 710 | T36: 591 | U36: 2626 | V36: 7201 | W36: 5542 | X36: 5257 | Y36: 3185 | AA36: 2252 | AB36: 3059 | AC36: 3918 | AD36: 2894 | AE36: 1771 | AF36: 4707 | AG36: 7362 | AH36: 1757
B37: Bifangst/Annet | C37: kg | D37: =SUM(E37:AI37) -> 0
B38: Koke-% reke | D38: =D36/D25 -> 0.18524865 | E38: =E36/E25 -> #DIV/0! | F38: =F36/F25 -> #DIV/0! | G38: =G36/G25 -> #DIV/0! | H38: =H36/H25 -> #DIV/0! | I38: =I36/I25 -> #DIV/0! | J38: =J36/J25 -> 0.58313317 | K38: =K36/K25 -> 0.23049666 | ... AM38: =AM36/AM25 -> #DIV/0!
A40: Maskin | B40: Bunkersforbruk | C40: ltr | D40: =SUM(E40:AI40) -> 460014 | E40: 4 | F40: 3 | G40: 3 | H40: 4 | I40: 15000 | J40: 18000 | K40: 17000 | L40: 18000 | M40: 17000 | N40: 18000 | O40: 17000 | P40: 18000 | Q40: 18000 | R40: 18000 | S40: 18000 | T40: 18000 | U40: 19000 | V40: 18000 | W40: 18000 | X40: 17000 | Y40: 17000 | Z40: 16000 | AA40: 15000 | AB40: 19000 | AC40: 18000 | AD40: 19000 | AE40: 17000 | AF40: 16000 | AG40: 16000 | AH40: 15000 | AI40: 10000 | AJ40: 6000 | AK40: 0 | AL40: 0 | AM40: 0
B41: Smørolje forbruk | C41: ltr | D41: =SUM(E41:AI41) -> 1300 | E41: 0 | F41: 0 | G41: 0 | H41: 0 | I41: 0 | J41: 0 | K41: 0 | L41: 100 | N41: 0 | O41: 200 | Q41: 0 | R41: 0 | S41: 0 | T41: 0 | V41: 300 | Y41: 300 | AA41: 0 | AB41: 0 | AC41: 200 | AE41: 0 | AF41: 0 | AG41: 0 | AH41: 200 | AI41: 0 | AJ41: 200 | AK41: 0 | AL41: 0 | AM41: 0
A45: Fabrikk | B45: Timer uten produksjon, totalt | C45: timer | D45: =SUM(E45:AI45) -> 0 | E45: 0 | F45: 0 | G45: 0 | H45: 0 | I45: 0 | J45: 0 | K45: 0 | L45: 0 | M45: 0 | N45: 0 | O45: 0 | P45: 0 | Q45: 0 | R45: 0 | S45: 0 | T45: 0 | U45: 0 | V45: 0 | W45: 0 | X45: 0 | Y45: 0 | Z45: 0 | AA45: 0 | AB45: 0 | AC45: 0 | AD45: 0 | AE45: 0 | AF45: 0 | AG45: 0 | AH45: 0 | AI45: 0 | AJ45: 0 | AK45: 0 | AL45: 0 | AM45: 0
B46: Mangel på fisk | C46: timer | D46: =SUM(E46:AI46) -> 0 | E46: 0 | F46: 0 | G46: 0 | H46: 0 | I46: 0 | J46: 0 | K46: 0 | L46: 0 | M46: 0 | N46: 0 | O46: 0 | P46: 0 | Q46: 0 | R46: 0 | S46: 0 | T46: 0 | U46: 0 | V46: 0 | W46: 0 | X46: 0 | Y46: 0 | Z46: 0 | AA46: 0 | AB46: 0 | AC46: 0 | AD46: 0 | AE46: 0 | AF46: 0 | AG46: 0 | AH46: 0 | AI46: 0 | AJ46: 0 | AK46: 0 | AL46: 0 | AM46: 0
B47: Tekniske problem | C47: timer | D47: =SUM(E47:AI47) -> 0 | E47: 0 | F47: 0 | G47: 0 | H47: 0 | I47: 0 | J47: 0 | K47: 0 | L47: 0 | M47: 0 | N47: 0 | O47: 0 | P47: 0 | Q47: 0 | R47: 0 | S47: 0 | T47: 0 | U47: 0 | V47: 0 | W47: 0 | X47: 0 | Y47: 0 | Z47: 0 | AA47: 0 | AB47: 0 | AC47: 0 | AD47: 0 | AE47: 0 | AF47: 0 | AG47: 0 | AH47: 0 | AI47: 0 | AJ47: 0 | AK47: 0 | AL47: 0 | AM47: 0
B48: Andre årsaker | C48: timer | D48: =SUM(E48:AI48) -> 0 | E48: 0 | F48: 0 | G48: 0 | H48: 0 | I48: 0 | J48: 0 | K48: 0 | L48: 0 | M48: 0 | N48: 0 | O48: 0 | P48: 0 | Q48: 0 | R48: 0 | S48: 0 | T48: 0 | U48: 0 | V48: 0 | W48: 0 | X48: 0 | Y48: 0 | Z48: 0 | AA48: 0 | AB48: 0 | AC48: 0 | AD48: 0 | AE48: 0 | AF48: 0 | AG48: 0 | AH48: 0 | AI48: 0 | AJ48: 0 | AK48: 0 | AL48: 0 | AM48: 0
B49: Ensilasje, råstoff | C49: kg | D49: =SUM(E49:Y49) -> 0 | E49: 0 | F49: 0 | G49: 0 | H49: 0 | K49: 0 | N49: 0 | AE49: 0 | AF49: 0 | AG49: 0 | AH49: 0 | AI49: 0 | AJ49: 0 | AK49: 0 | AL49: 0 | AM49: 0
...

Sheet Tur 4 2022
B2: Navn | C2: "Breidtind"
B3: Turnr | C3: 3
B4: Tur start | C4: 44693
B5: Tur slutt | C5: 44726
B7: Aktivitet | D7: Totalt | E7: 44693 | F7: =E7+1 -> 44694 | G7: =F7+1 -> 44695 | H7: =G7+1 -> 44696 | I7: =H7+1 -> 44697 | J7: =I7+1 -> 44698 | K7: =J7+1 -> 44699 | L7: =K7+1 -> 44700 | M7: =L7+1 -> 44701 | ... AM7: =AL7+1 -> 44727
B8: Fiske | C8: timer | D8: =SUM(E8:AI8) -> 660 | E8: 0 | F8: 14.5 | G8: 24 | H8: 24 | I8: 24 | J8: 24 | K8: 24 | L8: 24 | M8: 24 | N8: 24 | O8: 24 | P8: 24 | Q8: 24 | R8: 19 | S8: 18 | T8: 20 | U8: 22 | V8: 24 | W8: 24 | X8: 24 | Y8: 24 | Z8: 24 | AA8: 24 | AB8: 24 | AC8: 24 | AD8: 24 | AE8: 24 | AF8: 24 | AG8: 7 | AH8: 24 | AI8: 7.5 | AJ8: 0 | AK8: 0 | AL8: 0 | AM8: 0
B9: Seiling | C9: timer | D9: =SUM(E9:AI9) -> 67 | E9: 24 | F9: 9.5 | G9: 0 | H9: 0 | I9: 0 | J9: 0 | K9: 0 | L9: 0 | M9: 0 | N9: 0 | O9: 0 | P9: 0 | Q9: 0 | R9: 5 | S9: 6 | T9: 4 | U9: 2 | V9: 0 | W9: 0 | X9: 0 | Y9: 0 | Z9: 0 | AA9: 0 | AB9: 0 | AC9: 0 | AD9: 0 | AE9: 0 | AF9: 0 | AG9: 0 | AH9: 0 | AI9: 16.5 | AJ9: 0 | AK9: 0 | AL9: 0 | AM9: 0
B10: Teknisk (feil, problem) | C10: timer | D10: =SUM(E10:AI10) -> 0 | E10: 0 | F10: 0 | G10: 0 | H10: 0 | I10: 0 | J10: 0 | K10: 0 | L10: 0 | M10: 0 | N10: 0 | O10: 0 | P10: 0 | Q10: 0 | R10: 0 | S10: 0 | T10: 0 | U10: 0 | V10: 0 | W10: 0 | X10: 0 | Y10: 0 | Z10: 0 | AA10: 0 | AB10: 0 | AC10: 0 | AD10: 0 | AE10: 0 | AF10: 0 | AG10: 0 | AH10: 0 | AI10: 0 | AJ10: 0 | AK10: 0 | AL10: 0 | AM10: 0
B11: Vasking | C11: timer | D11: =SUM(E11:AI11) -> 0 | E11: 0 | F11: 0 | G11: 0 | H11: 0 | I11: 0 | J11: 0 | K11: 0 | L11: 0 | M11: 0 | N11: 0 | O11: 0 | P11: 0 | Q11: 0 | R11: 0 | S11: 0 | T11: 0 | U11: 0 | V11: 0 | W11: 0 | X11: 0 | Y11: 0 | Z11: 0 | AA11: 0 | AB11: 0 | AC11: 0 | AD11: 0 | AE11: 0 | AF11: 0 | AG11: 0 | AH11: 0 | AI11: 0 | AJ11: 0 | AK11: 0 | AL11: 0 | AM11: 0
B12: Lossing | C12: timer | D12: =SUM(E12:AI12) -> 0 | E12: 0 | F12: 0 | G12: 0 | H12: 0 | I12: 0 | J12: 0 | K12: 0 | L12: 0 | M12: 0 | N12: 0 | O12: 0 | P12: 0 | Q12: 0 | R12: 0 | S12: 0 | T12: 0 | U12: 0 | V12: 0 | W12: 0 | X12: 0 | Y12: 0 | Z12: 0 | AA12: 0 | AB12: 0 | AC12: 0 | AD12: 0 | AE12: 0 | AF12: 0 | AG12: 0 | AH12: 0 | AI12: 0 | AJ12: 0 | AK12: 0 | AL12: 0 | AM12: 0
B13: Bunkring | C13: timer | D13: =SUM(E13:AI13) -> 0 | E13: 0 | F13: 0 | G13: 0 | H13: 0 | I13: 0 | J13: 0 | K13: 0 | L13: 0 | M13: 0 | N13: 0 | O13: 0 | P13: 0 | Q13: 0 | R13: 0 | S13: 0 | T13: 0 | U13: 0 | V13: 0 | W13: 0 | X13: 0 | Y13: 0 | Z13: 0 | AA13: 0 | AB13: 0 | AC13: 0 | AD13: 0 | AE13: 0 | AF13: 0 | AG13: 0 | AH13: 0 | AI13: 0 | AJ13: 0 | AK13: 0 | AL13: 0 | AM13: 0
B14: Annet | C14: timer | D14: =SUM(E14:AI14) -> 17 | E14: 0 | F14: 0 | G14: 0 | H14: 0 | I14: 0 | J14: 0 | K14: 0 | L14: 0 | M14: 0 | N14: 0 | O14: 0 | P14: 0 | Q14: 0 | R14: 0 | S14: 0 | T14: 0 | U14: 0 | V14: 0 | W14: 0 | X14: 0 | Y14: 0 | Z14: 0 | AA14: 0 | AB14: 0 | AC14: 0 | AD14: 0 | AE14: 0 | AF14: 0 | AG14: 17 | AH14: 0 | AI14: 0 | AJ14: 0 | AK14: 0 | AL14: 0 | AM14: 0
B15: SUM | C15: timer | D15: =SUM(E15:AI15) -> 744 | E15: =SUM(E8:E14) -> 24 | F15: =SUM(F8:F14) -> 24 | G15: =SUM(G8:G14) -> 24 | H15: =SUM(H8:H14) -> 24 | I15: =SUM(I8:I14) -> 24 | J15: =SUM(J8:J14) -> 24 | K15: =SUM(K8:K14) -> 24 | L15: =SUM(L8:L14) -> 24 | ... AM15: =SUM(AM8:AM14) -> 0
B17: Felt/område | C17: Navn | D17: =SUM(E17:AI17) -> 0 | E17: Seilas | F17: Thor Iversen | G17: Thor Iversen | H17: Thor Iversen | I17: Thor Iversen | J17: Thor I | K17: Thor I | L17: Thor I | M17: Thor Iversen | N17: Thor I | O17: Thor I | P17: Thor Iversen | Q17: Thor I | R17: Thor I | S17: Havståholla | T17: Thor Iversen | U17: Hopendjupet Øst | V17: Hopendjupet | W17: Hopendjupet | X17: Hopendjupet | Y17: Hopendjupet | Z17: Hopendjupet | AA17: Hopendjupet | AB17: Hopendjupet | AC17: Hopendjupet | AD17: Hopendjupet | AE17: Hopendjupet | AF17: Hopen øst | AG17: Hopen øst | AH17: Hopen øst | AI17: Hopen øst
B18: Tauetimer | C18: Timer | D18: =SUM(E18:AI18) -> 549 | F18: 10 | G18: 21 | H18: 21.5 | I18: 20.2 | J18: 16.1 | K18: 21 | L18: 20.5 | M18: 21.4 | N18: 17 | O18: 20.3 | P18: 21 | Q18: 21 | R18: 15.5 | S18: 15 | T18: 17 | U18: 20.5 | V18: 18.5 | W18: 21 | X18: 16 | Y18: 21.5 | Z18: 20.5 | AA18: 19.5 | AB18: 21.5 | AC18: 21.5 | AD18: 16.5 | AE18: 19.5 | AF18: 21.5 | AG18: 7 | AH18: 18 | AI18: 7.5
B19: Hal | C19: Antall | D19: =SUM(E19:AI19) -> 102 | F19: 2 | G19: 4 | H19: 4 | I19: 4 | J19: 3 | K19: 4 | L19: 4 | M19: 4 | N19: 3 | O19: 4 | P19: 4 | Q19: 4 | R19: 3 | S19: 3 | T19: 3 | U19: 4 | V19: 3 | W19: 4 | X19: 3 | Y19: 4 | Z19: 4 | AA19: 4 | AB19: 4 | AC19: 4 | AD19: 3 | AE19: 3 | AF19: 4 | AG19: 1 | AH19: 3 | AI19: 1
B20: Bruk (630/550) (eks 2xAlfredo) | C20: Type x antall | D20: =SUM(E20:AI20) -> 0 | F20: 3*C3000 | G20: 3*C3000 | H20: 3*C3000 | I20: 3*C3000 | J20: 3*C3000 | K20: 3*c3000 | L20: 3*C3000 | M20: 3*C3000 | N20: 3*C3000 | O20: 3*C3000 | P20: 3*C3000 | Q20: 3*c3000 | R20: 3*c3000 | S20: 3*C3000 | T20: 3*c3000 | U20: 3*C3000 | V20: 3*c3000 | W20: 3*C3000 | X20: 3*c3000 | Y20: 3*c3000 | Z20: 3*c3000 | AA20: 3*c3000 | AB20: 3*c3000 | AC20: 3*c3000 | AD20: 3*c3000 | AE20: 3*c3000 | AF20: 3*c3000 | AG20: 2*c3000 | AH20: 3*c3000 | AI20: 3*C3000
B21: Sjøtemperatur | C21: Grader | F21: 1.4 | G21: 1.6 | H21: 2.2 | I21: 2.1 | J21: 2.1 | K21: 1.9 | L21: 2 | M21: 2.1 | N21: 1.7 | O21: 1.4 | P21: 1.8 | Q21: 1.2 | R21: 1.5 | S21: 1.1 | T21: 0.8 | U21: 1.1 | V21: 1 | W21: 0.6 | X21: 1.1 | Y21: 1.1 | Z21: 1.2 | AA21: 0.8 | AB21: 0.8 | AC21: 0.8 | AD21: 0.3 | AE21: 0.5 | AF21: 0.5 | AG21: 0.4 | AH21: 0.2 | AI21: 0.6
B23: Fangst pr tauetime kg | C23: =D25/D18 -> 1011.9617
A25: efangst | B25: Fangst total(produktvekt) | C25: (autosummering) | D25: =SUM(E25:AI25) -> 555567 | E25: =SUM(E26:E37) -> 0 | F25: =SUM(F26:F37) -> 9695 | G25: =SUM(G26:G37) -> 22201 | H25: =SUM(H26:H37) -> 21897 | I25: =SUM(I26:I37) -> 22457 | J25: =SUM(J26:J37) -> 19341 | K25: =SUM(K26:K37) -> 20769 | L25: =SUM(L26:L37) -> 20284 | ... AM25: =SUM(AM26:AM37) -> 0
B26: Torsk | C26: kg | D26: =SUM(E26:AI26) -> 0
B27: Hyse | C27: kg | D27: =SUM(E27:AI27) -> 0
B28: Sei N | C28: kg | D28: =SUM(E28:AI28) -> 0
B29: Sei S | C29: kg | D29: =SUM(E29:Y29) -> 0
B30: Uer rund | C30: kg | D30: =SUM(E30:AI30) -> 0
B31: Uer j/c | C31: kg | D31: =SUM(E31:AI31) -> 0
B32: Uer hoder | C32: kg | D32: =SUM(E32:AI32) -> 0
B33: Blåkveite | C33: kg | D33: =SUM(E33:AL33) -> 0
B34: Blåkveite hoder | C34: kg | D34: =SUM(E34:AI34) -> 0
B35: Reke | C35: kg | D35: =SUM(E35:AI35) -> 479504 | F35: 8190 | G35: 17598 | H35: 18165 | I35: 18354 | J35: 16716 | K35: 16359 | L35: 16464 | M35: 10395 | N35: 9723 | O35: 15374 | P35: 14175 | Q35: 11340 | R35: 8421 | S35: 5838 | T35: 8862 | U35: 16674 | V35: 16800 | W35: 22071 | X35: 14491 | Y35: 15729 | Z35: 16002 | AA35: 14469 | AB35: 21945 | AC35: 19026 | AD35: 20139 | AE35: 34860 | AF35: 25221 | AG35: 3570 | AH35: 30353 | AI35: 12180
B36: Reke kok | C36: kg | D36: =SUM(E36:AI36) -> 76063 | F36: 1505 | G36: 4603 | H36: 3732 | I36: 4103 | J36: 2625 | K36: 4410 | L36: 3820 | M36: 5068 | N36: 3255 | O36: 2514 | P36: 2651 | Q36: 4610 | R36: 1526 | S36: 1435 | T36: 2674 | U36: 3483 | V36: 529 | W36: 3314 | X36: 1216 | Y36: 3334 | Z36: 2414 | AA36: 3383 | AB36: 1785 | AC36: 2736 | AD36: 2873 | AE36: 799 | AF36: 1309 | AH36: 357
B37: Bifangst/Annet | C37: kg | D37: =SUM(E37:AI37) -> 0
B38: Koke-% reke | D38: =D36/D25 -> 0.13691058 | E38: =E36/E25 -> #DIV/0! | F38: =F36/F25 -> 0.15523466 | G38: =G36/G25 -> 0.207333 | H38: =H36/H25 -> 0.17043431 | I38: =I36/I25 -> 0.18270472 | J38: =J36/J25 -> 0.13572204 | K38: =K36/K25 -> 0.21233569 | ... AM38: =AM36/AM25 -> #DIV/0!
A40: Maskin | B40: Bunkersforbruk | C40: ltr | D40: =SUM(E40:AI40) -> 513000 | E40: 14000 | F40: 16000 | G40: 16000 | H40: 16000 | I40: 16000 | J40: 17000 | K40: 18000 | L40: 17000 | M40: 16000 | N40: 17000 | O40: 17000 | P40: 17000 | Q40: 17000 | R40: 17000 | S40: 17000 | T40: 17000 | U40: 18000 | V40: 17000 | W40: 17000 | X40: 16000 | Y40: 17000 | Z40: 17000 | AA40: 17000 | AB40: 19000 | AC40: 18000 | AD40: 16000 | AE40: 17000 | AF40: 17000 | AG40: 8000 | AH40: 17000 | AI40: 17000 | AJ40: 0 | AK40: 0 | AL40: 0 | AM40: 0
B41: Smørolje forbruk | C41: ltr | D41: =SUM(E41:AI41) -> 1900 | E41: 0 | F41: 100 | G41: 0 | H41: 200 | I41: 0 | J41: 0 | K41: 0 | L41: 200 | M41: 0 | N41: 0 | O41: 0 | P41: 200 | Q41: 0 | R41: 0 | S41: 0 | T41: 200 | U41: 100 | V41: 0 | W41: 0 | X41: 200 | Z41: 200 | AA41: 0 | AB41: 0 | AC41: 300 | AD41: 0 | AE41: 0 | AF41: 0 | AG41: 200 | AH41: 0 | AI41: 0 | AJ41: 0 | AK41: 0 | AL41: 0 | AM41: 0
A45: Fabrikk | B45: Timer uten produksjon, totalt | C45: timer | D45: =SUM(E45:AI45) -> 0 | E45: 0 | F45: 0 | G45: 0 | H45: 0 | I45: 0 | J45: 0 | K45: 0 | L45: 0 | M45: 0 | N45: 0 | O45: 0 | P45: 0 | Q45: 0 | R45: 0 | S45: 0 | T45: 0 | U45: 0 | V45: 0 | W45: 0 | X45: 0 | Y45: 0 | Z45: 0 | AA45: 0 | AB45: 0 | AC45: 0 | AD45: 0 | AE45: 0 | AF45: 0 | AG45: 0 | AH45: 0 | AI45: 0 | AJ45: 0 | AK45: 0 | AL45: 0 | AM45: 0
B46: Mangel på fisk | C46: timer | D46: =SUM(E46:AI46) -> 0 | E46: 0 | F46: 0 | G46: 0 | H46: 0 | I46: 0 | J46: 0 | K46: 0 | L46: 0 | M46: 0 | N46: 0 | O46: 0 | P46: 0 | Q46: 0 | R46: 0 | S46: 0 | T46: 0 | U46: 0 | V46: 0 | W46: 0 | X46: 0 | Y46: 0 | Z46: 0 | AA46: 0 | AB46: 0 | AC46: 0 | AD46: 0 | AE46: 0 | AF46: 0 | AG46: 0 | AH46: 0 | AI46: 0 | AJ46: 0 | AK46: 0 | AL46: 0 | AM46: 0
B47: Tekniske problem | C47: timer | D47: =SUM(E47:AI47) -> 2.5 | E47: 0 | F47: 0 | G47: 0 | H47: 0 | I47: 0 | J47: 0 | K47: 0 | L47: 0 | M47: 0 | N47: 0 | O47: 0 | P47: 2.5 | Q47: 0 | R47: 0 | S47: 0 | T47: 0 | U47: 0 | V47: 0 | W47: 0 | X47: 0 | Y47: 0 | Z47: 0 | AA47: 0 | AB47: 0 | AC47: 0 | AD47: 0 | AE47: 0 | AF47: 0 | AG47: 0 | AH47: 0 | AI47: 0 | AJ47: 0 | AK47: 0 | AL47: 0 | AM47: 0
B48: Andre årsaker | C48: timer | D48: =SUM(E48:AI48) -> 0 | E48: 0 | F48: 0 | G48: 0 | H48: 0 | I48: 0 | J48: 0 | K48: 0 | L48: 0 | M48: 0 | N48: 0 | O48: 0 | P48: 0 | Q48: 0 | R48: 0 | S48: 0 | T48: 0 | U48: 0 | V48: 0 | W48: 0 | X48: 0 | Y48: 0 | Z48: 0 | AA48: 0 | AB48: 0 | AC48: 0 | AD48: 0 | AE48: 0 | AF48: 0 | AG48: 0 | AH48: 0 | AI48: 0 | AJ48: 0 | AK48: 0 | AL48: 0 | AM48: 0
B49: Ensilasje, råstoff | C49: kg | D49: =SUM(E49:Y49) -> 0 | E49: 0 | F49: 0 | G49: 0 | H49: 0 | K49: 0 | N49: 0 | AE49: 0 | AF49: 0 | AG49: 0 | AH49: 0 | AI49: 0 | AJ49: 0 | AK49: 0 | AL49: 0 | AM49: 0
...

Sheet Tur 5 2022
B2: Navn | C2: "Breidtind"
B3: Turnr | C3: 5
B4: Tur start | C4: 44693
B5: Tur slutt | C5: 44726
B7: Aktivitet | D7: Totalt | E7: 44726 | F7: =E7+1 -> 44727 | G7: =F7+1 -> 44728 | H7: =G7+1 -> 44729 | I7: =H7+1 -> 44730 | J7: =I7+1 -> 44731 | K7: =J7+1 -> 44732 | L7: =K7+1 -> 44733 | M7: =L7+1 -> 44734 | ... AP7: =AO7+1 -> 44763
B8: Fiske | C8: timer | D8: =SUM(E8:AI8) -> 564 | E8: 0 | F8: 0 | G8: 0 | H8: 18 | I8: 17 | J8: 18 | K8: 24 | L8: 22 | M8: 24 | N8: 24 | O8: 24 | P8: 24 | Q8: 24 | R8: 16 | S8: 24 | T8: 24 | U8: 22 | V8: 16 | W8: 24 | X8: 24 | Y8: 17 | Z8: 24 | AA8: 21 | AB8: 17 | AC8: 24 | AD8: 24 | AE8: 9 | AF8: 0 | AG8: 11 | AH8: 24 | AI8: 24 | AJ8: 19 | AK8: 9 | AL8: 24 | AM8: 24 | AN8: 6 | AO8: 0 | AP8: 0
B9: Seiling | C9: timer | D9: =SUM(E9:AI9) -> 109 | E9: 0 | F9: 0 | G9: 13 | H9: 6 | I9: 7 | J9: 6 | K9: 0 | L9: 2 | M9: 0 | N9: 0 | O9: 0 | Q9: 0 | R9: 8 | S9: 0 | T9: 0 | U9: 2 | V9: 8 | W9: 0 | X9: 0 | Y9: 7 | Z9: 0 | AA9: 3 | AB9: 5 | AC9: 0 | AD9: 0 | AE9: 15 | AF9: 14 | AG9: 13 | AH9: 0 | AI9: 0 | AJ9: 5 | AK9: 15 | AL9: 0 | AM9: 0 | AN9: 0 | AO9: 0 | AP9: 0
B10: Teknisk (feil, problem) | C10: timer | D10: =SUM(E10:AI10) -> 0 | E10: 0 | F10: 0 | G10: 0 | H10: 0 | I10: 0 | J10: 0 | K10: 0 | L10: 0 | M10: 0 | N10: 0 | O10: 0 | P10: 0 | Q10: 0 | R10: 0 | S10: 0 | T10: 0 | U10: 0 | V10: 0 | W10: 0 | X10: 0 | Y10: 0 | Z10: 0 | AA10: 0 | AB10: 0 | AC10: 0 | AD10: 0 | AE10: 0 | AF10: 0 | AG10: 0 | AH10: 0 | AI10: 0 | AJ10: 0 | AK10: 0 | AL10: 0 | AM10: 0 | AN10: 0 | AO10: 0 | AP10: 0
B11: Vasking | C11: timer | D11: =SUM(E11:AI11) -> 0 | E11: 0 | F11: 0 | G11: 0 | H11: 0 | I11: 0 | J11: 0 | K11: 0 | L11: 0 | M11: 0 | N11: 0 | O11: 0 | P11: 0 | Q11: 0 | R11: 0 | S11: 0 | T11: 0 | U11: 0 | V11: 0 | W11: 0 | X11: 0 | Y11: 0 | Z11: 0 | AA11: 0 | AB11: 0 | AC11: 0 | AD11: 0 | AE11: 0 | AF11: 0 | AG11: 0 | AH11: 0 | AI11: 0 | AJ11: 0 | AK11: 0 | AL11: 0 | AM11: 0 | AN11: 18 | AO11: 24 | AP11: 0
B12: Lossing | C12: timer | D12: =SUM(E12:AI12) -> 10 | E12: 0 | F12: 0 | G12: 0 | H12: 0 | I12: 0 | J12: 0 | K12: 0 | L12: 0 | M12: 0 | N12: 0 | O12: 0 | P12: 0 | Q12: 0 | R12: 0 | S12: 0 | T12: 0 | U12: 0 | V12: 0 | W12: 0 | X12: 0 | Y12: 0 | Z12: 0 | AA12: 0 | AB12: 0 | AC12: 0 | AD12: 0 | AE12: 0 | AF12: 10 | AG12: 0 | AH12: 0 | AI12: 0 | AJ12: 0 | AK12: 0 | AL12: 0 | AM12: 0 | AN12: 0 | AO12: 0 | AP12: 0
B13: Bunkring | C13: timer | D13: =SUM(E13:AI13) -> 5 | E13: 0 | F13: 0 | G13: 5 | H13: 0 | I13: 0 | J13: 0 | K13: 0 | L13: 0 | M13: 0 | N13: 0 | O13: 0 | P13: 0 | Q13: 0 | R13: 0 | S13: 0 | T13: 0 | U13: 0 | V13: 0 | W13: 0 | X13: 0 | Y13: 0 | Z13: 0 | AA13: 0 | AB13: 0 | AC13: 0 | AD13: 0 | AE13: 0 | AF13: 0 | AG13: 0 | AH13: 0 | AI13: 0 | AJ13: 0 | AK13: 0 | AL13: 0 | AM13: 0 | AN13: 0 | AO13: 0 | AP13: 0
B14: Annet | C14: timer | D14: =SUM(E14:AI14) -> 54 | E14: 24 | F14: 24 | G14: 6 | H14: 0 | I14: 0 | J14: 0 | K14: 0 | L14: 0 | M14: 0 | N14: 0 | O14: 0 | P14: 0 | Q14: 0 | R14: 0 | S14: 0 | T14: 0 | U14: 0 | V14: 0 | W14: 0 | X14: 0 | Y14: 0 | Z14: 0 | AA14: 0 | AB14: 0 | AC14: 0 | AD14: 0 | AE14: 0 | AF14: 0 | AH14: 0 | AI14: 0 | AJ14: 0 | AK14: 0 | AL14: 0 | AM14: 0 | AN14: 0 | AO14: 0 | AP14: 0
B15: SUM | C15: timer | D15: =SUM(E15:AI15) -> 742 | E15: =SUM(E8:E14) -> 24 | F15: =SUM(F8:F14) -> 24 | G15: =SUM(G8:G14) -> 24 | H15: =SUM(H8:H14) -> 24 | I15: =SUM(I8:I14) -> 24 | J15: =SUM(J8:J14) -> 24 | K15: =SUM(K8:K14) -> 24 | L15: =SUM(L8:L14) -> 24 | ... AP15: =SUM(AP8:AP14) -> 0
B17: Felt/område | C17: Navn | D17: =SUM(E17:AI17) -> 0 | E17: 0 | F17: 0 | G17: 0 | H17: 0 | I17: Teisten | J17: teisten | K17: tromsøflaket | L17: tromsøflaket | M17: Tromsøflaket | N17: tromsøflaket | O17: tromsøflaket | P17: tromsøflaket | Q17: Tromsøflaket | R17: Tromsøflaket | S17: Bjørnøya | T17: Bjørnøya | U17: bjørnøya | V17: sørbakken | W17: tromsøflaket | X17: tromsøflaket | Y17: Tromsøflaket | Z17: gardar | AA17: Gardarbanken | AB17: Sørbakken | AC17: sørbakken | AD17: sørbakken | AE17: sørbakken | AF17: 0 | AG17: sørbakken | AH17: sørbakken | AI17: sørbakken | AJ17: Fingerdypet | AK17: gardar | AL17: nygrunnen | AM17: nygrunnen
B18: Tauetimer | C18: Timer | D18: =SUM(E18:AI18) -> 179 | F18: 0 | G18: 0 | H18: 11,5 | I18: 10,5 | J18: 15 | K18: 18,5 | L18: 18 | M18: 13,5 | N18: 8 | O18: 16 | P18: 18,5 | Q18: 5,5 | R18: 16,5 | S18: 9 | T18: 14,5 | U18: 19 | V18: 13,5 | W18: 17 | X18: 13,5 | Y18: 15,5 | Z18: 12,5 | AA18: 17 | AB18: 10 | AC18: 12 | AD18: 17,5 | AE18: 9 | AF18: 0 | AG18: 4,5 | AH18: 13 | AI18: 16 | AJ18: 16 | AK18: 4,5 | AL18: 13 | AM18: 11
B19: Hal | C19: Antall | D19: =SUM(E19:AI19) -> 83 | F19: 0 | G19: 0 | H19: 2 | I19: 3 | J19: 3 | K19: 3 | L19: 3 | M19: 3 | N19: 2 | O19: 3 | P19: 4 | Q19: 2 | R19: 3 | S19: 3 | T19: 4 | U19: 4 | V19: 4 | W19: 4 | X19: 3 | Y19: 3 | Z19: 3 | AA19: 4 | AB19: 3 | AC19: 3 | AD19: 4 | AE19: 2 | AF19: 0 | AG19: 2 | AH19: 3 | AI19: 3 | AJ19: 3 | AK19: 3 | AL19: 3 | AM19: 4
B20: Bruk (630/550) (eks 2xAlfredo) | C20: Type x antall | D20: =SUM(E20:AI20) -> 1.5238095 | F20: 0 | G20: 0 | H20: 960 atlantic | I20: 2*630 | J20: 960 atlantic | K20: 960 atlantic | L20: 630*2 | M20: 630*2 | N20: 630*2 | O20: 960 atlantic | P20: 960 atlantic | Q20: 630*2 | R20: 630*2 | S20: 630*2 | T20: 630*2 | U20: 630*2 | V20: 630*2 | W20: 960 atlantic | X20: 960 atlantic | Y20: 1.5238095 | Z20: 630*2 | AA20: 630*2 | AB20: 630*2 | AC20: 630*2 | AD20: 63*2 | AE20: 630*2 | AF20: 0 | AG20: 630*2/atlantic 960 | AH20: 960 atlantic | AI20: 630*2 | AJ20: 630*2 | AK20: 630*2 | AL20: 63*2 | AM20: 630*2
B21: Sjøtemperatur | C21: Grader | I21: 8 | J21: 8 | K21: 6 | L21: 7 | M21: 7 | N21: 7 | O21: 8 | P21: 8 | Q21: 8 | R21: 8 | S21: 3 | T21: 4 | U21: 5 | V21: 8 | W21: 8 | X21: 9 | Y21: 7 | Z21: 6 | AA21: 6 | AB21: 9 | AC21: 9 | AD21: 9 | AE21: 9 | AG21: 8 | AH21: 10 | AI21: 9 | AK21: 8 | AL21: 8 | AM21: 8 | AN21: 8
B23: Fangst pr tauetime kg | C23: =D25/D18 -> 5959.7486
A25: efangst | B25: Fangst total(produktvekt) | C25: (autosummering) | D25: =SUM(E25:AP25) -> 1066795 | E25: =SUM(E26:E37) -> 0 | F25: =SUM(F26:F37) -> 0 | G25: =SUM(G26:G37) -> 0 | H25: =SUM(H26:H37) -> 3768 | I25: =SUM(I26:I37) -> 16024 | J25: =SUM(J26:J37) -> 31223 | K25: =SUM(K26:K37) -> 34854 | L25: =SUM(L26:L37) -> 30948 | ... AP25: =SUM(AP26:AP37) -> 0
B26: Torsk | C26: kg | D26: =SUM(E26:AP26) -> 175349 | I26: 138 | J26: 276 | M26: 733 | N26: 1058 | P26: 549 | Q26: 779 | R26: 8830 | S26: 22124 | T26: 18027 | U26: 20533 | V26: 1698 | Y26: 9565 | Z26: 49065 | AA26: 27719 | AB26: 959 | AC26: 2517 | AD26: 2065 | AE26: 688 | AG26: 320 | AI26: 1367 | AJ26: 2150 | AK26: 2801 | AL26: 498 | AM26: 890
B27: Hyse | C27: kg | D27: =SUM(E27:AP27) -> 67712 | H27: 48 | I27: 46 | J27: 230 | N27: 48 | R27: 5060 | S27: 11408 | T27: 33040 | U27: 9630 | V27: 46 | Y27: 920 | Z27: 4282 | AA27: 2538 | AD27: 48 | AK27: 368
B28: Sei N | C28: kg | D28: =SUM(E28:AP28) -> 192332 | I28: 14401 | J28: 27500 | U28: 543 | AK28: 36754 | AL28: 41156 | AM28: 71978
B29: Sei S | C29: kg | D29: =SUM(E29:AP29) -> 0
B30: Uer rund | C30: kg | D30: =SUM(E30:AP30) -> 4348 | AK30: 4348
B31: Uer j/c | C31: kg | D31: =SUM(E31:AP31) -> 472692 | H31: 1980 | I31: 380 | K31: 22110 | L31: 19140 | M31: 38207 | N31: 29713 | O31: 22885 | P31: 28566 | Q31: 22747 | R31: 18285 | V31: 14375 | W31: 30406 | X31: 37858 | Y31: 17457 | AB31: 30337 | AC31: 20194 | AD31: 12627 | AE31: 8280 | AG31: 20539 | AH31: 41462 | AI31: 28727 | AJ31: 6417
B32: Uer hoder | C32: kg | D32: =SUM(E32:AP32) -> 119468 | H32: 1740 | I32: 440 | K32: 12744 | L32: 11808 | N32: 828 | O32: 10152 | P32: 13482 | Q32: 1332 | R32: 12420 | V32: 9990 | W32: 11466 | X32: 12492 | Y32: 5526 | AB32: 5292 | AG32: 3888 | AH32: 4716 | AI32: 1152
B33: Blåkveite | C33: kg | D33: =SUM(E33:AP33) -> 18150 | M33: 858 | N33: 1100 | P33: 704 | Q33: 1760 | V33: 418 | AB33: 1056 | AC33: 2266 | AD33: 2112 | AE33: 1320 | AG33: 2134 | AI33: 3344 | AJ33: 1078
B34: Blåkveite hoder | C34: kg | D34: =SUM(E34:AP34) -> 0
B35: Reke | C35: kg | D35: =SUM(E35:AP35) -> 0
B36: Reke kok | C36: kg | D36: =SUM(E36:AP36) -> 0
B37: Bifangst/Annet | C37: kg | D37: =SUM(E37:AP37) -> 16744 | I37: 619 | J37: 3217 | S37: 315 | T37: 1585 | U37: 3125 | V37: 190 | Y37: 195 | Z37: 1550 | AA37: 2150 | AC37: 50 | AJ37: 900 | AK37: 1263 | AL37: 820 | AM37: 765
B38: Koke-% reke | D38: =D36/D25 -> 0 | E38: =E36/E25 -> #DIV/0! | F38: =F36/F25 -> #DIV/0! | G38: =G36/G25 -> #DIV/0! | H38: =H36/H25 -> 0 | I38: =I36/I25 -> 0 | J38: =J36/J25 -> 0 | K38: =K36/K25 -> 0 | ... AP38: =AP36/AP25 -> #DIV/0!
A40: Maskin | B40: Bunkersforbruk | C40: ltr | D40: =SUM(E40:AI40) -> 332000 | E40: 3000 | F40: 1000 | G40: 7000 | H40: 10000 | I40: 13000 | J40: 16000 | K40: 9000 | L40: 9000 | M40: 10000 | N40: 10000 | O40: 9000 | P40: 9000 | Q40: 10000 | R40: 13000 | S40: 14000 | T40: 14000 | U40: 15000 | V40: 14000 | W40: 10000 | X40: 9000 | Y40: 13000 | Z40: 11000 | AA40: 14000 | AB40: 14000 | AC40: 11000 | AD40: 11000 | AE40: 12000 | AF40: 8000 | AG40: 14000 | AH40: 8000 | AI40: 11000 | AJ40: 13000 | AK40: 16000 | AL40: 13000 | AM40: 13000 | AN40: 7000 | AO40: 5000 | AP40: 0
B41: Smørolje forbruk | C41: ltr | D41: =SUM(E41:AI41) -> 1300 | E41: 0 | G41: 0 | H41: 300 | I41: 0 | J41: 0 | K41: 0 | L41: 300 | M41: 0 | N41: 0 | O41: 0 | Q41: 0 | R41: 0 | S41: 0 | V41: 0 | W41: 0 | X41: 200 | AA41: 300 | AB41: 0 | AD41: 0 | AE41: 0 | AF41: 0 | AH41: 200 | AI41: 0 | AJ41: 0 | AK41: 0 | AL41: 0 | AM41: 0 | AN41: 0 | AO41: 200 | AP41: 0
A45: Fabrikk | B45: Timer uten produksjon, totalt | C45: timer | D45: =SUM(E45:AI45) -> 4 | E45: 0 | F45: 0 | G45: 0 | H45: 0 | I45: 0 | J45: 0 | K45: 4 | L45: 0 | M45: 0 | N45: 0 | O45: 0 | P45: 0 | Q45: 0 | R45: 0 | S45: 0 | T45: 0 | U45: 0 | V45: 0 | W45: 0 | X45: 0 | Y45: 0 | Z45: 0 | AA45: 0 | AB45: 0 | AC45: 0 | AD45: 0 | AE45: 0 | AF45: 0 | AG45: 0 | AH45: 0 | AI45: 0 | AJ45: 0 | AK45: 0 | AL45: 0 | AM45: 0 | AN45: 0 | AO45: 0 | AP45: 0
B46: Mangel på fisk | C46: timer | D46: =SUM(E46:AI46) -> 0 | E46: 0 | F46: 0 | G46: 0 | H46: 0 | I46: 0 | J46: 0 | K46: 0 | L46: 0 | M46: 0 | N46: 0 | O46: 0 | P46: 0 | Q46: 0 | R46: 0 | S46: 0 | T46: 0 | U46: 0 | V46: 0 | W46: 0 | X46: 0 | Y46: 0 | Z46: 0 | AA46: 0 | AB46: 0 | AC46: 0 | AD46: 0 | AE46: 0 | AF46: 0 | AG46: 0 | AH46: 0 | AI46: 0 | AJ46: 0 | AK46: 0 | AL46: 0 | AM46: 0 | AN46: 0 | AO46: 0 | AP46: 0
B47: Tekniske problem | C47: timer | D47: =SUM(E47:AI47) -> 4 | E47: 0 | F47: 0 | G47: 0 | H47: 0 | I47: 0 | J47: 0 | K47: 4 | L47: 0 | M47: 0 | N47: 0 | O47: 0 | Q47: 0 | R47: 0 | S47: 0 | T47: 0 | U47: 0 | V47: 0 | W47: 0 | X47: 0 | Y47: 0 | Z47: 0 | AA47: 0 | AB47: 0 | AC47: 0 | AD47: 0 | AE47: 0 | AF47: 0 | AG47: 0 | AH47: 0 | AI47: 0 | AJ47: 0 | AK47: 0 | AL47: 0 | AM47: 0 | AN47: 0 | AO47: 0 | AP47: 0
B48: Andre årsaker | C48: timer | D48: =SUM(E48:AI48) -> 0 | E48: 0 | F48: 0 | G48: 0 | H48: 0 | I48: 0 | J48: 0 | K48: 0 | L48: 0 | M48: 0 | N48: 0 | O48: 0 | P48: 0 | Q48: 0 | R48: 0 | S48: 0 | T48: 0 | U48: 0 | V48: 0 | W48: 0 | X48: 0 | Y48: 0 | Z48: 0 | AA48: 0 | AB48: 0 | AC48: 0 | AD48: 0 | AE48: 0 | AF48: 0 | AG48: 0 | AH48: 0 | AI48: 0 | AJ48: 0 | AK48: 0 | AL48: 0 | AM48: 0 | AN48: 0 | AO48: 0 | AP48: 0
B49: Ensilasje, råstoff | C49: kg | D49: =SUM(E49:Y49) -> 167000 | E49: 0 | F49: 0 | G49: 0 | H49: 0 | I49: 4000 | J49: 6000 | K49: 8000 | L49: 6000 | M49: 10000 | N49: 8000 | O49: 0 | P49: 15000 | Q49: 8000 | R49: 23000 | S49: 30000 | T49: 30000 | U49: 6000 | W49: 5000 | X49: 5000 | Y49: 3000 | Z49: 27000 | AA49: 20000 | AB49: 0 | AE49: 0 | AF49: 0 | AG49: 0 | AH49: 0 | AI49: 0 | AJ49: 0 | AK49: 22000 | AL49: 20000 | AM49: 30000 | AN49: 0 | AO49: 0 | AP49: 0
...

Sheet Tur 6 2022
B2: Navn | C2: "Breidtind"
B3: Turnr | C3: 6
B4: Tur start | C4: 44763
B5: Tur slutt | C5: 44797
B7: Aktivitet | D7: Totalt | E7: 44764 | F7: 44765 | G7: 44766 | H7: 44767 | I7: 44768 | J7: 44769 | K7: 44770 | L7: 44771 | M7: 44772 | N7: 44773 | O7: 44774 | P7: 44775 | Q7: 44776 | R7: 44777 | S7: 44778 | T7: 44779 | U7: 44780 | V7: 44781 | W7: 44782 | X7: 44783 | Y7: 44784 | Z7: 44785 | AA7: 44786 | AB7: 44787 | AC7: 44788 | AD7: 44789 | AE7: 44790 | AF7: 44791 | AG7: 44792 | AH7: 44793 | AI7: 44794 | AJ7: 44795 | AK7: 44796 | AL7: 44797
B8: Fiske | C8: timer | D8: =SUM(E8:AL8) -> 400.5 | E8: 1.5 | F8: 8 | G8: 24 | H8: 18 | I8: 24 | J8: 24 | K8: 24 | L8: 24 | M8: 24 | N8: 7 | O8: 24 | P8: 24 | Q8: 24 | R8: 24 | S8: 24 | T8: 24 | U8: 24 | V8: 24 | W8: 24 | X8: 6 | Y8: 0 | Z8: 0 | AA8: 0 | AB8: 0 | AC8: 0 | AD8: 0 | AE8: 0 | AF8: 0 | AG8: 0 | AH8: 0 | AI8: 0 | AJ8: 0 | AK8: 0 | AL8: 0
B9: Seiling | C9: timer | D9: =SUM(E9:AI9) -> 73.5 | E9: 20.5 | F9: 16 | G9: 0 | H9: 6 | I9: 0 | J9: 0 | K9: 0 | L9: 0 | M9: 0 | N9: 0 | O9: 0 | P9: 0 | Q9: 0 | R9: 0 | S9: 0 | T9: 0 | U9: 0 | V9: 0 | W9: 0 | X9: 6 | Y9: 15 | Z9: 10 | AA9: 0 | AB9: 0 | AC9: 0 | AD9: 0 | AE9: 0 | AF9: 0 | AG9: 0 | AH9: 0 | AI9: 0 | AJ9: 0 | AK9: 0 | AL9: 0
B10: Teknisk (feil, problem) | C10: timer | D10: =SUM(E10:AI10) -> 65 | E10: 0 | F10: 0 | G10: 0 | H10: 0 | I10: 0 | J10: 0 | K10: 0 | L10: 0 | M10: 0 | N10: 17 | O10: 0 | P10: 0 | Q10: 0 | R10: 0 | S10: 0 | T10: 0 | U10: 0 | V10: 0 | W10: 0 | X10: 12 | Y10: 9 | Z10: 3 | AA10: 24 | AB10: 0 | AC10: 0 | AD10: 0 | AE10: 0 | AF10: 0 | AG10: 0 | AH10: 0 | AI10: 0 | AJ10: 0 | AK10: 0 | AL10: 0
B11: Vasking | C11: timer | D11: =SUM(E11:AI11) -> 0 | E11: 0 | F11: 0 | G11: 0 | H11: 0 | I11: 0 | J11: 0 | K11: 0 | L11: 0 | M11: 0 | N11: 0 | O11: 0 | P11: 0 | Q11: 0 | R11: 0 | S11: 0 | T11: 0 | U11: 0 | V11: 0 | W11: 0 | X11: 0 | Y11: 0 | Z11: 0 | AA11: 0 | AB11: 0 | AC11: 0 | AD11: 0 | AE11: 0 | AF11: 0 | AG11: 0 | AH11: 0 | AI11: 0 | AJ11: 0 | AK11: 0 | AL11: 0
B12: Lossing | C12: timer | D12: =SUM(E12:AI12) -> 11 | E12: 0 | F12: 0 | G12: 0 | H12: 0 | I12: 0 | J12: 0 | K12: 0 | L12: 0 | M12: 0 | N12: 0 | O12: 0 | P12: 0 | Q12: 0 | R12: 0 | S12: 0 | T12: 0 | U12: 0 | V12: 0 | W12: 0 | X12: 0 | Y12: 0 | Z12: 11 | AA12: 0 | AB12: 0 | AC12: 0 | AD12: 0 | AE12: 0 | AF12: 0 | AG12: 0 | AH12: 0 | AI12: 0 | AJ12: 0 | AK12: 0 | AL12: 0
B13: Bunkring | C13: timer | D13: =SUM(E13:AI13) -> 2 | E13: 2 | F13: 0 | G13: 0 | H13: 0 | I13: 0 | J13: 0 | K13: 0 | L13: 0 | M13: 0 | N13: 0 | O13: 0 | P13: 0 | Q13: 0 | R13: 0 | S13: 0 | T13: 0 | U13: 0 | V13: 0 | W13: 0 | X13: 0 | Y13: 0 | Z13: 0 | AA13: 0 | AB13: 0 | AC13: 0 | AD13: 0 | AE13: 0 | AF13: 0 | AG13: 0 | AH13: 0 | AI13: 0 | AJ13: 0 | AK13: 0 | AL13: 0
B14: Annet | C14: timer | D14: =SUM(E14:AI14) -> 3 | E14: 0 | F14: 0 | G14: 0 | H14: 0 | I14: 0 | J14: 0 | K14: 0 | L14: 0 | M14: 0 | N14: 0 | O14: 0 | P14: 0 | Q14: 0 | R14: 0 | S14: 0 | T14: 0 | U14: 0 | V14: 0 | W14: 0 | X14: 0 | Y14: 0 | Z14: 3 | AA14: 0 | AB14: 0 | AC14: 0 | AD14: 0 | AE14: 0 | AF14: 0 | AG14: 0 | AH14: 0 | AI14: 0 | AJ14: 0 | AK14: 0 | AL14: 0
B15: SUM | C15: timer | D15: =SUM(E15:AI15) -> 555 | E15: =SUM(E8:E14) -> 24 | F15: =SUM(F8:F14) -> 24 | G15: =SUM(G8:G14) -> 24 | H15: =SUM(H8:H14) -> 24 | I15: =SUM(I8:I14) -> 24 | J15: =SUM(J8:J14) -> 24 | K15: =SUM(K8:K14) -> 24 | L15: =SUM(L8:L14) -> 24 | ... AL15: =SUM(AL8:AL14) -> 0
B17: Felt/område | C17: Navn | D17: =SUM(E17:AI17) -> 0 | E17: NØS | F17: Hopen | G17: Hopen | H17: Hopen | I17: Storfjordrenna | J17: Storfjordr | K17: Storfjordrenna | L17: Storfjord | M17: Storfjordrenna | N17: Storfjordrenna | O17: Storfjordrenna | P17: Hopen | Q17: Hopen øst | R17: Hopen øst | S17: Hopen Øst | T17: Hopen øst | U17: Hopen øst | V17: Hopen øst | W17: Storfjordbanken | X17: Gardar | Y17: Gardar | Z17: Tromsø | AA17: Tromsø
B18: Tauetimer | C18: Timer | D18: =SUM(E18:AI18) -> 282 | E18: 1 | F18: 5 | G18: 22 | H18: 15.5 | I18: 16.5 | J18: 16 | K18: 26 | L18: 17 | M18: 13 | N18: 15 | O18: 6.5 | P18: 14.5 | Q18: 8 | R18: 16 | S18: 20.5 | T18: 23.5 | U18: 18 | V18: 14 | W18: 9 | X18: 5
B19: Hal | C19: Antall | D19: =SUM(E19:AI19) -> 56 | E19: 1 | F19: 1 | G19: 4 | H19: 3 | I19: 3 | J19: 3 | K19: 4 | L19: 3 | M19: 2 | N19: 2 | O19: 1 | P19: 4 | Q19: 5 | R19: 3 | S19: 4 | T19: 4 | U19: 3 | V19: 3 | W19: 2 | X19: 1
B20: Bruk (630/550) (eks 2xAlfredo) | C20: Type x antall | D20: =SUM(E20:AI20) -> 0 | E20: 2*630 | F20: 2*630 | G20: 2*630 | H20: 2*630 | I20: 2*630 | J20: 2*630 | K20: 2*630 | L20: 2*630 | M20: 2*630 | N20: 2*630 | O20: 2*630 | P20: 2*630 | Q20: 2*630 | R20: 2*630 | S20: 2*630 | T20: 2*630 | U20: 2*630 | V20: 2*630 | W20: 1,5*630 | X20: 2*630
B21: Sjøtemperatur | C21: Grader
B23: Fangst pr tauetime kg | C23: =D25/D18 -> 1625.0745
A25: efangst | B25: Fangst total(produktvekt) | C25: (autosummering) | D25: =SUM(E25:AP25) -> 458271 | E25: =SUM(E26:E37) -> 1058 | F25: =SUM(F26:F37) -> 5402 | G25: =SUM(G26:G37) -> 37196 | H25: =SUM(H26:H37) -> 9961 | I25: =SUM(I26:I37) -> 24360 | J25: =SUM(J26:J37) -> 38266 | K25: =SUM(K26:K37) -> 50056 | L25: =SUM(L26:L37) -> 50386 | ... AL25: =SUM(AL26:AL37) -> 0
B26: Torsk | C26: kg | D26: =SUM(E26:AP26) -> 432868 | E26: 1058 | F26: 4740 | G26: 34600 | H26: 9275 | I26: 23928 | J26: 36541 | K26: 47658 | L26: 48742 | M26: 15377 | N26: 13693 | O26: 8230 | P26: 4994 | Q26: 4162 | R26: 26559 | S26: 60282 | T26: 48260 | U26: 33329 | V26: 6216 | W26: 2926 | X26: 2298 | Y26: 0 | Z26: 0 | AA26: 0 | AB26: 0 | AC26: 0 | AD26: 0 | AE26: 0 | AF26: 0 | AG26: 0 | AH26: 0 | AI26: 0 | AJ26: 0 | AK26: 0 | AL26: 0
B27: Hyse | C27: kg | D27: =SUM(E27:AP27) -> 10330 | F27: 418 | G27: 1896 | H27: 336 | I27: 432 | J27: 1440 | K27: 2160 | L27: 336 | M27: 96 | N27: 48 | O27: 48 | P27: 96 | Q27: 0 | R27: 0 | S27: 528 | T27: 288 | U27: 672 | V27: 144 | W27: 624 | X27: 768 | Y27: 0 | Z27: 0 | AA27: 0 | AB27: 0 | AC27: 0 | AD27: 0 | AE27: 0 | AF27: 0 | AG27: 0 | AH27: 0 | AI27: 0 | AJ27: 0 | AK27: 0 | AL27: 0
B28: Sei N | C28: kg | D28: =SUM(E28:AP28) -> 0 | K28: 0 | L28: 0 | M28: 0 | N28: 0 | O28: 0 | P28: 0 | Q28: 0 | R28: 0 | S28: 0 | T28: 0 | U28: 0 | V28: 0 | W28: 0 | X28: 0 | Y28: 0 | Z28: 0 | AA28: 0 | AB28: 0 | AC28: 0 | AD28: 0 | AE28: 0 | AF28: 0 | AG28: 0 | AH28: 0 | AI28: 0 | AJ28: 0 | AK28: 0 | AL28: 0
B29: Sei S | C29: kg | D29: =SUM(E29:AP29) -> 0 | K29: 0 | L29: 0 | M29: 0 | N29: 0 | O29: 0 | P29: 0 | Q29: 0 | R29: 0 | S29: 0 | T29: 0 | U29: 0 | V29: 0 | W29: 0 | X29: 0 | Y29: 0 | Z29: 0 | AA29: 0 | AB29: 0 | AC29: 0 | AD29: 0 | AE29: 0 | AF29: 0 | AG29: 0 | AH29: 0 | AI29: 0 | AJ29: 0 | AK29: 0 | AL29: 0
B30: Uer rund | C30: kg | D30: =SUM(E30:AP30) -> 7496 | K30: 0 | L30: 0 | M30: 7496 | N30: 0 | O30: 0 | P30: 0 | Q30: 0 | R30: 0 | S30: 0 | T30: 0 | U30: 0 | V30: 0 | W30: 0 | X30: 0 | Y30: 0 | Z30: 0 | AA30: 0 | AB30: 0 | AC30: 0 | AD30: 0 | AE30: 0 | AF30: 0 | AG30: 0 | AH30: 0 | AI30: 0 | AJ30: 0 | AK30: 0 | AL30: 0
B31: Uer j/c | C31: kg | D31: =SUM(E31:AP31) -> 816 | K31: 0 | L31: 0 | M31: 0 | N31: 0 | O31: 0 | P31: 0 | Q31: 0 | R31: 0 | S31: 0 | T31: 0 | U31: 0 | V31: 0 | W31: 0 | X31: 816 | Y31: 0 | Z31: 0 | AA31: 0 | AB31: 0 | AC31: 0 | AD31: 0 | AE31: 0 | AF31: 0 | AG31: 0 | AH31: 0 | AI31: 0 | AJ31: 0 | AK31: 0 | AL31: 0
B32: Uer hoder | C32: kg | D32: =SUM(E32:AP32) -> 648 | K32: 0 | L32: 0 | M32: 0 | N32: 0 | O32: 0 | P32: 0 | Q32: 0 | R32: 0 | S32: 0 | T32: 0 | U32: 0 | V32: 0 | W32: 0 | X32: 648 | Y32: 0 | Z32: 0 | AA32: 0 | AB32: 0 | AC32: 0 | AD32: 0 | AE32: 0 | AF32: 0 | AG32: 0 | AH32: 0 | AI32: 0 | AJ32: 0 | AK32: 0 | AL32: 0
